Workbook
Name IQ_CH: 110000
Name IQ_CQ: 5000
Name IQ_CY: 10000
Name IQ_DAILY: 500000
Name IQ_FH: 100000
Name IQ_FQ: 500
Name IQ_FY: 1000
Name IQ_LTM: 2000
Name IQ_MONTH: 15000
Name IQ_NTM: 6000
Name IQ_WEEK: 50000
Name IQ_YTD: 3000

Sheet Summary
B2: Summary
A4: x | B4: BLSH Standalone Summary
B5: Current share price | C5: 32.6 | E5: 46216
B6: Diluted shares outstanding (mm) | C6: 151.64835 | E6: 46216
B7: Market capitalization ($mm) | C7: =C5*C6 -> 4943.7361
B8: Total debt ($mm) | C8: 507 | E8: 46112
B9: Total cash ($mm) | C9: =76+728 -> 804 | E9: 46112
B10: Net debt ($mm) | C10: =C8-C9 -> -297 | E10: 46112
B11: Enterprise value ($mm) | C11: =C7+C10 -> 4646.7361
B13: EV / Revenue (2026P) | C13: =+Summary!C11/'P&L'!E12 -> 11.503359
B14: EV / EBITDA (2026P) | C14: =+C11/'P&L'!E37 -> 13.4688
A16: x | B16: COMPANY-SPECIFIC OPERATING ASSUMPTIONS
B17: Liquidity Service Growth | C17: Bull
B18: Volume Growth | C18: Bull
A20: x | B20: Pro Forma Summary
B21: Current share price | C21: 22.85 | E21: 46216
B22: Diluted shares outstanding (mm) | C22: =+C6+61.07 -> 212.71835 | E22: 46216 | F22: Using the disclosed structure $2.35B of newly-issued shares at a locked VWAP of $38.4797: $2.35B / $38.4797 = ≈ 61.07 million new Ordinary Shares
B23: Market capitalization ($mm) | C23: =C21*C22 -> 4860.6142
B24: Total debt ($mm) | C24: =+C8+1850 -> 2357 | E24: 46112 | F24: Bullish to assume Equiniti's existing $1.85B debt comprised of a $1.5B term loan (S + 3.75%, maturity December 2031), $350M of senior notes (8.5%, maturity November 2029) and $235M undrawn revolver (S + 3.75%, maturity December 2030)
B25: Total cash ($mm) | C25: =76+728 -> 804 | E25: 46112
B26: Net debt ($mm) | C26: =C24-C25 -> 1553 | E26: 46112
B27: Enterprise value ($mm) | C27: =C23+C26 -> 6413.6142
B29: Risk Profile
B30: Net Leverage | C30: =+C26/'P&L'!E45 -> 4.454055
B31: Interest Coverage | C31: =+'P&L'!E45 / 210 -> 1.6603383 | F31: Adjusted Net Income assumes $190M to $210M of interest expense, D&A, other and taxes of ~$30M
B33: EV / Revenue (2026P) | C33: =+Summary!C27/'P&L'!E41 -> 4.8626813
B34: EV / EBITDA (2026P) | C34: =+C27/'P&L'!E45 -> 18.394456
B36: Methodology | C36: EV | D36: Share Price | E36: Current Discount
B37: Comps — EV/EBITDA | C37: =+Valuation!C6 -> 12229.898 | D37: =+Valuation!D6 -> 50.19265 | E37: =+D37/$C$21 -1 -> 1.1966149
B38: Comps — EV/Revenue | C38: =+Valuation!C7 -> 27585.108 | D38: =+Valuation!D7 -> 122.37829 | E38: =+D38/$C$21 -1 -> 4.355724
B39: Sum-of-the-parts | C39: =+Valuation!C8 -> 20580.447 | D39: =+Valuation!D8 -> 89.449018 | E39: =+D39/$C$21 -1 -> 2.9146179
B40: DCF | C40: =+Valuation!C9 -> 11324.144 | D40: =+Valuation!D9 -> 45.934657 | E40: =+D40/$C$21 -1 -> 1.0102694

Sheet Valuation
B2: Valuation Summary — Football Field
B4: METHODOLOGY RANGE SUMMARY
B5: Methodology | C5: EV | D5: Share Price | E5: Source / tab
B6: Comps — EV/EBITDA | C6: =C15*Comps!J13 -> 12229.898 | D6: =+(C6-$C$16)/$C$17 -> 50.19265 | E6: Comps tab based on Modern Trading Platform median multiple
B7: Comps — EV/Revenue | C7: =C14*Comps!F13 -> 27585.108 | D7: =+(C7-$C$16)/$C$17 -> 122.37829 | E7: Comps tab based on Modern Trading Platform median multiple
B8: Sum-of-the-parts | C8: =+('P&L'!H9*Comps!E25)+('P&L'!H10*Comps!E44)+('P&L'!H11*Comps!E52)+('P&L'!H31*Comps!E29) -> 20580.447 | D8: =+(C8-$C$16)/$C$17 -> 89.449018 | E8: Trading Revenue * Modern Trading Platform + Liquidity Revenue * Tokenization Infra. + CoinDesk * Data and Index + Equiniti * Computershare
B9: DCF | C9: =+DCF!C25 -> 11324.144 | D9: =+(C9-$C$16)/$C$17 -> 45.934657 | E9: DCF tab
B10: 52-week trading range | D10: $21.76 - $118.00 | E10: Market data
B11: Analyst consensus target range | E11: [Street estimates source]
B14: Pro Forma Revenue 2029P | C14: ='P&L'!H41 -> 3065.012
B15: Pro Forma EBITDA 2026P | C15: ='P&L'!H45 -> 855.23759
B16: Less: net debt ($mm) | C16: =+Summary!C26 -> 1553
B17: Diluted shares (mm) | C17: =+Summary!C22 -> 212.71835

Sheet P&L
B2: Income Statement - Bullish (BLSH) Standalone
J4: =YEAR(J5) -> 2024 | K4: =YEAR(K5) -> 2024 | L4: =YEAR(L5) -> 2024 | M4: =YEAR(M5) -> 2024 | N4: =YEAR(N5) -> 2025 | O4: =YEAR(O5) -> 2025 | P4: =YEAR(P5) -> 2025 | Q4: =YEAR(Q5) -> 2025 | ... AG4: =YEAR(AG5) -> 2029
J5: 45354 | K5: =EOMONTH(J5,3) -> 45473 | L5: =EOMONTH(K5,3) -> 45565 | M5: =EOMONTH(L5,3) -> 45657 | N5: =EOMONTH(M5,3) -> 45747 | O5: =EOMONTH(N5,3) -> 45838 | P5: =EOMONTH(O5,3) -> 45930 | Q5: =EOMONTH(P5,3) -> 46022 | R5: =EOMONTH(Q5,3) -> 46112 | ... AG5: =EOMONTH(AF5,3) -> 47483
A6: x | B6: BLSH P&L Summary
B7: ($mm unless noted) | C7: 2024 | D7: 2025 | E7: 2026 | F7: 2027 | G7: 2028 | H7: 2029 | J7: ="Q" & INT((MONTH(J5)-1)/3)+1 & " " & YEAR(J5) -> Q1 2024 | K7: ="Q" & INT((MONTH(K5)-1)/3)+1 & " " & YEAR(K5) -> Q2 2024 | L7: ="Q" & INT((MONTH(L5)-1)/3)+1 & " " & YEAR(L5) -> Q3 2024 | M7: ="Q" & INT((MONTH(M5)-1)/3)+1 & " " & YEAR(M5) -> Q4 2024 | N7: ="Q" & INT((MONTH(N5)-1)/3)+1 & " " & YEAR(N5) -> Q1 2025 | O7: ="Q" & INT((MONTH(O5)-1)/3)+1 & " " & YEAR(O5) -> Q2 2025 | P7: ="Q" & INT((MONTH(P5)-1)/3)+1 & " " & YEAR(P5) -> Q3 2025 | Q7: ="Q" & INT((MONTH(Q5)-1)/3)+1 & " " & YEAR(Q5) -> Q4 2025 | ... AG7: ="Q" & INT((MONTH(AG5)-1)/3)+1 & " " & YEAR(AG5) -> Q4 2029
B8: Volume ($B) | D8: =+SUMIFS($J$8:$AG$8,$J$4:$AG$4,D$7) -> 796.2 | E8: =+SUMIFS($J$8:$AG$8,$J$4:$AG$4,E$7) -> 702.08683 | F8: =+SUMIFS($J$8:$AG$8,$J$4:$AG$4,F$7) -> 1387.4999 | G8: =+SUMIFS($J$8:$AG$8,$J$4:$AG$4,G$7) -> 3485.2421 | H8: =+SUMIFS($J$8:$AG$8,$J$4:$AG$4,H$7) -> 8754.5325 | N8: =+'Revenue Build'!C13 -> 252 | O8: =+'Revenue Build'!D13 -> 179.7 | P8: =+'Revenue Build'!E13 -> 142.2 | Q8: =+'Revenue Build'!F13 -> 222.3 | R8: =+'Revenue Build'!G13 -> 196.8 | S8: =+'Revenue Build'!H13 -> 130.8 | T8: =+'Revenue Build'!I13 -> 177.76145 | U8: =+'Revenue Build'!J13 -> 196.72538 | ... AG8: =+'Revenue Build'!V13 -> 2991.4963
B9: Transaction Revenue | C9: =+SUMIFS($J$9:$AG$9,$J$4:$AG$4,C$7) -> 153.254 | D9: =+SUMIFS($J$9:$AG$9,$J$4:$AG$4,D$7) -> 130.733 | E9: =+SUMIFS($J9:$AG9,$J$4:$AG$4,E$7) -> 139.549 | F9: =+SUMIFS($J9:$AG9,$J$4:$AG$4,F$7) -> 227.92504 | G9: =+SUMIFS($J9:$AG9,$J$4:$AG$4,G$7) -> 471.54494 | H9: =+SUMIFS($J9:$AG9,$J$4:$AG$4,H$7) -> 977.9252 | J9: =+'Income Statement'!J40 -> 44.474 | K9: =+'Income Statement'!K40 -> 34.909 | L9: =+'Income Statement'!L40 -> 32.875 | M9: =+'Income Statement'!M40 -> 40.996 | N9: =+'Income Statement'!N40 -> 42.043 | O9: =+'Income Statement'!O40 -> 24.056 | P9: =+'Income Statement'!P40 -> 26.705 | Q9: =+'Income Statement'!Q40 -> 37.929 | ... AG9: =+'Income Statement'!AG40 -> 314.93928
B10: Liquidity Subscription | C10: =+'Income Statement'!C41-C11 -> 23.784 | D10: =+'Income Statement'!D41-D11 -> 103.495 | E10: =+SUMIFS($J10:$AG10,$J$4:$AG$4,E$7) -> 236.84244 | F10: =+SUMIFS($J10:$AG10,$J$4:$AG$4,F$7) -> 361.08491 | G10: =+SUMIFS($J10:$AG10,$J$4:$AG$4,G$7) -> 634.0446 | H10: =+SUMIFS($J10:$AG10,$J$4:$AG$4,H$7) -> 1113.3463 | J10: =+'Income Statement'!J41 -> 8.8 | K10: =+'Income Statement'!K41 -> 25.8 | L10: =+'Income Statement'!L41 -> 11.5 | M10: =+'Income Statement'!M41 -> 13.684 | N10: =+'Income Statement'!N41 -> 19.741 | O10: =+'Income Statement'!O41 -> 31.9 | P10: =+'Income Statement'!P41 -> 49.3 | Q10: =+'Income Statement'!Q41 -> 54.554 | ... S10: =+'Income Statement'!S41 -> 62.689 | T10: =+'Revenue Build'!I35 -> 56.668945 | U10: =+'Revenue Build'!J35 -> 62.714497 | V10: =+'Revenue Build'!K35 -> 72.193078 | W10: =+'Revenue Build'!L35 -> 83.104239 | X10: =+'Revenue Build'!M35 -> 95.664497 | Y10: =+'Revenue Build'!N35 -> 110.1231 | Z10: =+'Revenue Build'!O35 -> 126.76695 | AA10: =+'Revenue Build'!P35 -> 145.92632 | ... AG10: =+'Revenue Build'!V35 -> 339.54657
B11: CoinDesk (Data, Insights, Indices) | C11: =27+9 -> 36 | D11: =34+18 -> 52 | E11: =+SUMIFS($J11:$AG11,$J$4:$AG$4,E$7) -> 27.554589 | F11: =+SUMIFS($J11:$AG11,$J$4:$AG$4,F$7) -> 59.235358 | G11: =+SUMIFS($J11:$AG11,$J$4:$AG$4,G$7) -> 65.420661 | H11: =+SUMIFS($J11:$AG11,$J$4:$AG$4,H$7) -> 72.533761 | T11: =+SUM('Revenue Build'!I31:I32) -> 13.615235 | U11: =+SUM('Revenue Build'!J31:J32) -> 13.939355 | V11: =+SUM('Revenue Build'!K31:K32) -> 14.275 | W11: =+SUM('Revenue Build'!L31:L32) -> 14.62258 | X11: =+SUM('Revenue Build'!M31:M32) -> 14.98252 | Y11: =+SUM('Revenue Build'!N31:N32) -> 15.355258 | Z11: =+SUM('Revenue Build'!O31:O32) -> 15.74125 | AA11: =+SUM('Revenue Build'!P31:P32) -> 16.140967 | ... AG11: =+SUM('Revenue Build'!V31:V32) -> 18.856079
B12: Total Adjusted Revenue | C12: =SUM(C9:C11) -> 213.038 | D12: =SUM(D9:D11) -> 286.228 | E12: =SUM(E9:E11) -> 403.94603 | F12: =SUM(F9:F11) -> 648.24531 | G12: =SUM(G9:G11) -> 1171.0102 | H12: =SUM(H9:H11) -> 2163.8053 | J12: =SUM(J9:J11) -> 53.274 | K12: =SUM(K9:K11) -> 60.709 | L12: =SUM(L9:L11) -> 44.375 | M12: =SUM(M9:M11) -> 54.68 | N12: =SUM(N9:N11) -> 61.784 | O12: =SUM(O9:O11) -> 55.956 | P12: =SUM(P9:P11) -> 76.005 | Q12: =SUM(Q9:Q11) -> 92.483 | ... AG12: =SUM(AG9:AG11) -> 673.34193
D13: =D12/C12-1 -> 0.34355373 | E13: =E12/D12-1 -> 0.41127364 | F13: =F12/E12-1 -> 0.60478198 | G13: =G12/F12-1 -> 0.80643065 | H13: =H12/G12-1 -> 0.84781078
B15: Administrative expenses | C15: =SUMIFS($J15:$AG15,$J$4:$AG$4,C$7) -> -153.119 | D15: =SUMIFS($J15:$AG15,$J$4:$AG$4,D$7) -> -182.188 | E15: =SUMIFS($J15:$AG15,$J$4:$AG$4,E$7) -> -219.16383 | F15: =SUMIFS($J15:$AG15,$J$4:$AG$4,F$7) -> -326.52288 | G15: =SUMIFS($J15:$AG15,$J$4:$AG$4,G$7) -> -542.46313 | H15: =SUMIFS($J15:$AG15,$J$4:$AG$4,H$7) -> -915.39376 | J15: ='Income Statement'!J13 -> -36.757 | K15: ='Income Statement'!K13 -> -39.662 | L15: ='Income Statement'!L13 -> -39.618 | M15: ='Income Statement'!M13 -> -37.082 | N15: ='Income Statement'!N13 -> -47.186 | O15: ='Income Statement'!O13 -> -43.017 | P15: ='Income Statement'!P13 -> -45.709 | Q15: ='Income Statement'!Q13 -> -46.276 | ... S15: ='Income Statement'!S13 -> -56.268 | T15: =-T12*T16 -> -56.038733 | U15: =-U12*U16 -> -58.577096 | V15: =-V12*V16 -> -67.048341 | W15: =-W12*W16 -> -77.302445 | X15: =-X12*X16 -> -85.249379 | Y15: =-Y12*Y16 -> -96.922714 | Z15: =-Z12*Z16 -> -110.79589 | AA15: =-AA12*AA16 -> -126.0608 | ... AG15: =-AG12*AG16 -> -276.03427
B16: % of revenue | C16: =-C15/C12 -> 0.71874032 | D16: =-D15/D12 -> 0.63651355 | E16: =-E15/E12 -> 0.5425572 | F16: 0.15 | G16: 0.13 | H16: 0.1 | J16: =-J15/J12 -> 0.68996133 | K16: =-K15/K12 -> 0.65331335 | L16: =-L15/L12 -> 0.8928 | M16: =-M15/M12 -> 0.67816386 | N16: =-N15/N12 -> 0.76372524 | O16: =-O15/O12 -> 0.76876474 | P16: =-P15/P12 -> 0.60139465 | Q16: =-Q15/Q12 -> 0.50037304 | ... S16: =-S15/S12 -> 0.60908535 | T16: =AVERAGE(P16:S16) - $AH$16 -> 0.53279614 | U16: =AVERAGE(Q16:T16) - $AH$16 -> 0.51564651 | V16: =AVERAGE(R16:U16) - $AH$16 -> 0.51946488 | W16: =AVERAGE(S16:V16) - $AH$16 -> 0.51924822 | X16: =AVERAGE(T16:W16) - $AH$16 -> 0.49678894 | Y16: =AVERAGE(U16:X16) - $AH$16 -> 0.48778714 | Z16: =AVERAGE(V16:Y16) - $AH$16 -> 0.48082229 | AA16: =AVERAGE(W16:Z16) - $AH$16 -> 0.47116165 | ... AG16: =AVERAGE(AC16:AF16) - $AH$16 -> 0.40994665 | AH16: 0.025
B17: Finance Expenses | C17: =SUMIFS($J17:$AG17,$J$4:$AG$4,C$7) -> -46.081 | D17: =SUMIFS($J17:$AG17,$J$4:$AG$4,D$7) -> -60.425 | E17: =SUMIFS($J17:$AG17,$J$4:$AG$4,E$7) -> -117.42302 | F17: =SUMIFS($J17:$AG17,$J$4:$AG$4,F$7) -> -116.68416 | G17: =SUMIFS($J17:$AG17,$J$4:$AG$4,G$7) -> -210.78184 | H17: =SUMIFS($J17:$AG17,$J$4:$AG$4,H$7) -> -389.48495 | J17: ='Income Statement'!J14 -> -9.916 | K17: ='Income Statement'!K14 -> -16.72 | L17: ='Income Statement'!L14 -> -6.81 | M17: ='Income Statement'!M14 -> -12.635 | N17: ='Income Statement'!N14 -> -15.063 | O17: ='Income Statement'!O14 -> -17.362 | P17: ='Income Statement'!P14 -> -13.608 | Q17: ='Income Statement'!Q14 -> -14.392 | ... S17: ='Income Statement'!S14 -> -32.513 | T17: =-T12*T18 -> -18.932142 | U17: =-U12*U18 -> -20.447879 | V17: =-V12*V18 -> -23.23295 | W17: =-W12*W18 -> -26.79728 | X17: =-X12*X18 -> -30.888144 | Y17: =-Y12*Y18 -> -35.765782 | Z17: =-Z12*Z18 -> -41.477405 | AA17: =-AA12*AA18 -> -48.159573 | ... AG17: =-AG12*AG18 -> -121.20155
B18: % of revenue | C18: =-C17/C12 -> 0.21630413 | D18: =-D17/D12 -> 0.21110793 | E18: =-E17/E12 -> 0.29068987 | F18: =-F17/F12 -> 0.18 | G18: =-G17/G12 -> 0.18 | H18: =-H17/H12 -> 0.18 | J18: =-J17/J12 -> 0.18613207 | K18: =-K17/K12 -> 0.27541221 | L18: =-L17/L12 -> 0.15346479 | M18: =-M17/M12 -> 0.23107169 | N18: =-N17/N12 -> 0.24380098 | O18: =-O17/O12 -> 0.31027951 | P18: =-P17/P12 -> 0.17904085 | Q18: =-Q17/Q12 -> 0.15561779 | ... S18: =-S17/S12 -> 0.35194413 | T18: =$AH$18 -> 0.18 | U18: =$AH$18 -> 0.18 | V18: =$AH$18 -> 0.18 | W18: =$AH$18 -> 0.18 | X18: =$AH$18 -> 0.18 | Y18: =$AH$18 -> 0.18 | Z18: =$AH$18 -> 0.18 | AA18: =$AH$18 -> 0.18 | ... AG18: =$AH$18 -> 0.18 | AH18: 0.18
B19: Other expenses | C19: =SUMIFS($J19:$AG19,$J$4:$AG$4,C$7) -> -38.529 | D19: =SUMIFS($J19:$AG19,$J$4:$AG$4,D$7) -> -52.369 | E19: =SUMIFS($J19:$AG19,$J$4:$AG$4,E$7) -> -63.688136 | F19: =SUMIFS($J19:$AG19,$J$4:$AG$4,F$7) -> -102.8223 | G19: =SUMIFS($J19:$AG19,$J$4:$AG$4,G$7) -> -185.87471 | H19: =SUMIFS($J19:$AG19,$J$4:$AG$4,H$7) -> -343.48823 | J19: ='Income Statement'!J15 -> -8.929 | K19: ='Income Statement'!K15 -> -9.063 | L19: ='Income Statement'!L15 -> -9.878 | M19: ='Income Statement'!M15 -> -10.659 | N19: ='Income Statement'!N15 -> -10.24 | O19: ='Income Statement'!O15 -> -13.291 | P19: ='Income Statement'!P15 -> -13.906 | Q19: ='Income Statement'!Q15 -> -14.932 | ... S19: ='Income Statement'!S15 -> -14.459 | T19: =-T12*T20 -> -17.164211 | U19: =-U12*U20 -> -17.976925 | V19: =-V12*V20 -> -20.321923 | W19: =-W12*W20 -> -23.648629 | X19: =-X12*X20 -> -27.359017 | Y19: =-Y12*Y20 -> -31.492729 | Z19: =-Z12*Z20 -> -36.536154 | AA19: =-AA12*AA20 -> -42.496509 | ... AG19: =-AG12*AG20 -> -106.8796
B20: % of revenue | C20: =-C19/C12 -> 0.18085506 | D20: =-D19/D12 -> 0.18296253 | E20: =-E19/E12 -> 0.15766496 | F20: =-F19/F12 -> 0.15861634 | G20: =-G19/G12 -> 0.15873023 | H20: =-H19/H12 -> 0.15874267 | J20: =-J19/J12 -> 0.16760521 | K20: =-K19/K12 -> 0.14928594 | L20: =-L19/L12 -> 0.22260282 | M20: =-M19/M12 -> 0.19493416 | N20: =-N19/N12 -> 0.1657387 | O20: =-O19/O12 -> 0.23752591 | P20: =-P19/P12 -> 0.18296165 | Q20: =-Q19/Q12 -> 0.1614567 | ... S20: =-S19/S12 -> 0.15651463 | T20: =AVERAGE(P20:S20) -> 0.16319115 | U20: =AVERAGE(Q20:T20) -> 0.15824852 | V20: =AVERAGE(R20:U20) -> 0.15744648 | W20: =AVERAGE(S20:V20) -> 0.15885019 | X20: =AVERAGE(T20:W20) -> 0.15943409 | Y20: =AVERAGE(U20:X20) -> 0.15849482 | Z20: =AVERAGE(V20:Y20) -> 0.15855639 | AA20: =AVERAGE(W20:Z20) -> 0.15883387 | ... AG20: =AVERAGE(AC20:AF20) -> 0.15873005
B21: OpEx | C21: =C15+C17+C19 -> -237.729 | D21: =D15+D17+D19 -> -294.982 | E21: =E15+E17+E19 -> -400.27498 | F21: =F15+F17+F19 -> -546.02933 | G21: =G15+G17+G19 -> -939.11968 | H21: =H15+H17+H19 -> -1648.3669 | J21: =J15+J17+J19 -> -55.602 | K21: =K15+K17+K19 -> -65.445 | L21: =L15+L17+L19 -> -56.306 | M21: =M15+M17+M19 -> -60.376 | N21: =N15+N17+N19 -> -72.489 | O21: =O15+O17+O19 -> -73.67 | P21: =P15+P17+P19 -> -73.223 | Q21: =Q15+Q17+Q19 -> -75.6 | ... AG21: =AG15+AG17+AG19 -> -504.11541
B23: EBITDA | C23: =+C12+C21 -> -24.691 | D23: =+D12+D21 -> -8.754 | E23: =+E12+E21 -> 3.6710457 | F23: =+F12+F21 -> 102.21598 | G23: =+G12+G21 -> 231.89052 | H23: =+H12+H21 -> 515.43833 | J23: =+J12+J21 -> -2.328 | K23: =+K12+K21 -> -4.736 | L23: =+L12+L21 -> -11.931 | M23: =+M12+M21 -> -5.696 | N23: =+N12+N21 -> -10.705 | O23: =+O12+O21 -> -17.714 | P23: =+P12+P21 -> 2.782 | Q23: =+Q12+Q21 -> 16.883 | ... AG23: =+AG12+AG21 -> 169.22652
A25: x | B25: Equiniti P&L Summary
B26: ($mm unless noted) | C26: 2024 | D26: 2025 | E26: 2026 | F26: 2027 | G26: 2028 | H26: 2029
B27: Issuer & Holder Services | E27: 685 | F27: =+E27*(1+F28) -> 705.55 | G27: =+F27*(1+G28) -> 719.661 | H27: =+G27*(1+H28) -> 734.05422
B28: Growth | F28: 0.03 | G28: 0.02 | H28: 0.02
B29: Interest Income | E29: 230 | F29: =+E29*(1+F30) -> 218.5 | G29: =+F29*(1+G30) -> 196.65 | H29: =+G29*(1+H30) -> 167.1525
B30: Growth | F30: -0.05 | G30: -0.1 | H30: -0.15
B31: Total Revenue | E31: =+E27+E29 -> 915 | F31: =+F27+F29 -> 924.05 | G31: =+G27+G29 -> 916.311 | H31: =+H27+H29 -> 901.20672
B33: OpEx | E33: -505 | F33: =+-F31*F34 -> -509.99481 | G33: =+-G31*G34 -> -505.72356 | H33: =+-H31*H34 -> -497.38732
B34: % of Revenue | E34: =+-E33/E31 -> 0.55191257 | F34: =+E34 -> 0.55191257 | G34: =+F34 -> 0.55191257 | H34: =+G34 -> 0.55191257
B35: CapEx | E35: -65 | F35: =+-F31*F36 -> -65.642896 | G35: =+-G31*G36 -> -65.093131 | H35: =+-H31*H36 -> -64.02015
B36: % of Revenue | E36: =+-E35/E31 -> 0.071038251 | F36: =+E36 -> 0.071038251 | G36: =+F36 -> 0.071038251 | H36: =+G36 -> 0.071038251
B37: EBITDA | E37: =+E31+E33+E35 -> 345 | F37: =+F31+F33+F35 -> 348.4123 | G37: =+G31+G33+G35 -> 345.49431 | H37: =+H31+H33+H35 -> 339.79926
A39: x | B39: Pro Forma P&L Summary (Excluding synergies)
C40: 2024 | D40: 2025 | E40: 2026 | F40: 2027 | G40: 2028 | H40: 2029
B41: Total Revenue | E41: =+E12+E31 -> 1318.946 | F41: =+F12+F31 -> 1572.2953 | G41: =+G12+G31 -> 2087.3212 | H41: =+H12+H31 -> 3065.012
B43: OpEx | E43: =+E21+E33 -> -905.27498 | F43: =+F21+F33 -> -1056.0241 | G43: =+G21+G33 -> -1444.8432 | H43: =+H21+H33 -> -2145.7543
B44: CapEx | E44: =+E35 -> -65 | F44: =+F35 -> -65.642896 | G44: =+G35 -> -65.093131 | H44: =+H35 -> -64.02015
B45: EBITDA | E45: =+E41+E43+E44 -> 348.67105 | F45: =+F41+F43+F44 -> 450.62827 | G45: =+G41+G43+G44 -> 577.38483 | H45: =+H41+H43+H44 -> 855.23759

Sheet Revenue Build
B2: Revenue Build
B4: Revenue Build | Z4: Notes
C5: 1 | D5: =+C5+1 -> 2 | E5: =+D5+1 -> 3 | F5: =+E5+1 -> 4 | G5: =+F5+1 -> 5 | H5: =+G5+1 -> 6 | I5: =+H5+1 -> 7 | J5: =+I5+1 -> 8 | K5: =+J5+1 -> 9 | ... V5: =+U5+1 -> 20
C6: 2025 | D6: =+IF(MOD(D5,4)=1,C6+1,C6) -> 2025 | E6: =+IF(MOD(E5,4)=1,D6+1,D6) -> 2025 | F6: =+IF(MOD(F5,4)=1,E6+1,E6) -> 2025 | G6: =+IF(MOD(G5,4)=1,F6+1,F6) -> 2026 | H6: =+IF(MOD(H5,4)=1,G6+1,G6) -> 2026 | I6: =+IF(MOD(I5,4)=1,H6+1,H6) -> 2026 | J6: =+IF(MOD(J5,4)=1,I6+1,I6) -> 2026 | K6: =+IF(MOD(K5,4)=1,J6+1,J6) -> 2027 | ... V6: =+IF(MOD(V5,4)=1,U6+1,U6) -> 2029
C7: =+"Q"&IF(MOD(C5,4)=0,4,MOD(C5,4)) -> Q1 | D7: =+"Q"&IF(MOD(D5,4)=0,4,MOD(D5,4)) -> Q2 | E7: =+"Q"&IF(MOD(E5,4)=0,4,MOD(E5,4)) -> Q3 | F7: =+"Q"&IF(MOD(F5,4)=0,4,MOD(F5,4)) -> Q4 | G7: =+"Q"&IF(MOD(G5,4)=0,4,MOD(G5,4)) -> Q1 | H7: =+"Q"&IF(MOD(H5,4)=0,4,MOD(H5,4)) -> Q2 | I7: =+"Q"&IF(MOD(I5,4)=0,4,MOD(I5,4)) -> Q3 | J7: =+"Q"&IF(MOD(J5,4)=0,4,MOD(J5,4)) -> Q4 | ... V7: =+"Q"&IF(MOD(V5,4)=0,4,MOD(V5,4)) -> Q4
C8: =+C7 & " " &C6 -> Q1 2025 | D8: =+D7 & " " &D6 -> Q2 2025 | E8: =+E7 & " " &E6 -> Q3 2025 | F8: =+F7 & " " &F6 -> Q4 2025 | G8: =+G7 & " " &G6 -> Q1 2026 | H8: =+H7 & " " &H6 -> Q2 2026 | I8: =+I7 & " " &I6 -> Q3 2026 | J8: =+J7 & " " &J6 -> Q4 2026 | ... V8: =+V7 & " " &V6 -> Q4 2029
B9: Volume ($Bs)
B10: Spot | C10: =+SUMIFS('Monthly Metrics'!$C17:$BJ17,'Monthly Metrics'!$C$7:$BJ$7,'Revenue Build'!C$7,'Monthly Metrics'!$C$6:$BJ$6,'Revenue Build'!C$6) -> 229.6 | D10: =+SUMIFS('Monthly Metrics'!$C17:$BJ17,'Monthly Metrics'!$C$7:$BJ$7,'Revenue Build'!D$7,'Monthly Metrics'!$C$6:$BJ$6,'Revenue Build'!D$6) -> 163 | E10: =+SUMIFS('Monthly Metrics'!$C17:$BJ17,'Monthly Metrics'!$C$7:$BJ$7,'Revenue Build'!E$7,'Monthly Metrics'!$C$6:$BJ$6,'Revenue Build'!E$6) -> 130.4 | F10: =+SUMIFS('Monthly Metrics'!$C17:$BJ17,'Monthly Metrics'!$C$7:$BJ$7,'Revenue Build'!F$7,'Monthly Metrics'!$C$6:$BJ$6,'Revenue Build'!F$6) -> 205 | G10: =+SUMIFS('Monthly Metrics'!$C17:$BJ17,'Monthly Metrics'!$C$7:$BJ$7,'Revenue Build'!G$7,'Monthly Metrics'!$C$6:$BJ$6,'Revenue Build'!G$6) -> 175.7 | H10: =+SUMIFS('Monthly Metrics'!$C17:$BJ17,'Monthly Metrics'!$C$7:$BJ$7,'Revenue Build'!H$7,'Monthly Metrics'!$C$6:$BJ$6,'Revenue Build'!H$6) -> 113.5 | I10: =+SUMIFS('Monthly Metrics'!$C17:$BJ17,'Monthly Metrics'!$C$7:$BJ$7,'Revenue Build'!I$7,'Monthly Metrics'!$C$6:$BJ$6,'Revenue Build'!I$6) -> 159.57758 | J10: =+SUMIFS('Monthly Metrics'!$C17:$BJ17,'Monthly Metrics'!$C$7:$BJ$7,'Revenue Build'!J$7,'Monthly Metrics'!$C$6:$BJ$6,'Revenue Build'!J$6) -> 176.60162 | ... V10: =+SUMIFS('Monthly Metrics'!$C17:$BJ17,'Monthly Metrics'!$C$7:$BJ$7,'Revenue Build'!V$7,'Monthly Metrics'!$C$6:$BJ$6,'Revenue Build'!V$6) -> 2685.4851
B11: Options | C11: =+SUMIFS('Monthly Metrics'!$C18:$BJ18,'Monthly Metrics'!$C$7:$BJ$7,'Revenue Build'!C$7,'Monthly Metrics'!$C$6:$BJ$6,'Revenue Build'!C$6) -> 0 | D11: =+SUMIFS('Monthly Metrics'!$C18:$BJ18,'Monthly Metrics'!$C$7:$BJ$7,'Revenue Build'!D$7,'Monthly Metrics'!$C$6:$BJ$6,'Revenue Build'!D$6) -> 0 | E11: =+SUMIFS('Monthly Metrics'!$C18:$BJ18,'Monthly Metrics'!$C$7:$BJ$7,'Revenue Build'!E$7,'Monthly Metrics'!$C$6:$BJ$6,'Revenue Build'!E$6) -> 0 | F11: =+SUMIFS('Monthly Metrics'!$C18:$BJ18,'Monthly Metrics'!$C$7:$BJ$7,'Revenue Build'!F$7,'Monthly Metrics'!$C$6:$BJ$6,'Revenue Build'!F$6) -> 9 | G11: =+SUMIFS('Monthly Metrics'!$C18:$BJ18,'Monthly Metrics'!$C$7:$BJ$7,'Revenue Build'!G$7,'Monthly Metrics'!$C$6:$BJ$6,'Revenue Build'!G$6) -> 11.6 | H11: =+SUMIFS('Monthly Metrics'!$C18:$BJ18,'Monthly Metrics'!$C$7:$BJ$7,'Revenue Build'!H$7,'Monthly Metrics'!$C$6:$BJ$6,'Revenue Build'!H$6) -> 8.8 | I11: =+SUMIFS('Monthly Metrics'!$C18:$BJ18,'Monthly Metrics'!$C$7:$BJ$7,'Revenue Build'!I$7,'Monthly Metrics'!$C$6:$BJ$6,'Revenue Build'!I$6) -> 7.2816797 | J11: =+SUMIFS('Monthly Metrics'!$C18:$BJ18,'Monthly Metrics'!$C$7:$BJ$7,'Revenue Build'!J$7,'Monthly Metrics'!$C$6:$BJ$6,'Revenue Build'!J$6) -> 8.0585033 | ... V11: =+SUMIFS('Monthly Metrics'!$C18:$BJ18,'Monthly Metrics'!$C$7:$BJ$7,'Revenue Build'!V$7,'Monthly Metrics'!$C$6:$BJ$6,'Revenue Build'!V$6) -> 122.54129
B12: Perps | C12: =+SUMIFS('Monthly Metrics'!$C19:$BJ19,'Monthly Metrics'!$C$7:$BJ$7,'Revenue Build'!C$7,'Monthly Metrics'!$C$6:$BJ$6,'Revenue Build'!C$6) -> 22.4 | D12: =+SUMIFS('Monthly Metrics'!$C19:$BJ19,'Monthly Metrics'!$C$7:$BJ$7,'Revenue Build'!D$7,'Monthly Metrics'!$C$6:$BJ$6,'Revenue Build'!D$6) -> 16.7 | E12: =+SUMIFS('Monthly Metrics'!$C19:$BJ19,'Monthly Metrics'!$C$7:$BJ$7,'Revenue Build'!E$7,'Monthly Metrics'!$C$6:$BJ$6,'Revenue Build'!E$6) -> 11.8 | F12: =+SUMIFS('Monthly Metrics'!$C19:$BJ19,'Monthly Metrics'!$C$7:$BJ$7,'Revenue Build'!F$7,'Monthly Metrics'!$C$6:$BJ$6,'Revenue Build'!F$6) -> 8.3 | G12: =+SUMIFS('Monthly Metrics'!$C19:$BJ19,'Monthly Metrics'!$C$7:$BJ$7,'Revenue Build'!G$7,'Monthly Metrics'!$C$6:$BJ$6,'Revenue Build'!G$6) -> 9.5 | H12: =+SUMIFS('Monthly Metrics'!$C19:$BJ19,'Monthly Metrics'!$C$7:$BJ$7,'Revenue Build'!H$7,'Monthly Metrics'!$C$6:$BJ$6,'Revenue Build'!H$6) -> 8.5 | I12: =+SUMIFS('Monthly Metrics'!$C19:$BJ19,'Monthly Metrics'!$C$7:$BJ$7,'Revenue Build'!I$7,'Monthly Metrics'!$C$6:$BJ$6,'Revenue Build'!I$6) -> 10.902192 | J12: =+SUMIFS('Monthly Metrics'!$C19:$BJ19,'Monthly Metrics'!$C$7:$BJ$7,'Revenue Build'!J$7,'Monthly Metrics'!$C$6:$BJ$6,'Revenue Build'!J$6) -> 12.065259 | ... V12: =+SUMIFS('Monthly Metrics'!$C19:$BJ19,'Monthly Metrics'!$C$7:$BJ$7,'Revenue Build'!V$7,'Monthly Metrics'!$C$6:$BJ$6,'Revenue Build'!V$6) -> 183.46986
B13: Total Volume | C13: =SUM(C10:C12) -> 252 | D13: =SUM(D10:D12) -> 179.7 | E13: =SUM(E10:E12) -> 142.2 | F13: =SUM(F10:F12) -> 222.3 | G13: =SUM(G10:G12) -> 196.8 | H13: =SUM(H10:H12) -> 130.8 | I13: =SUM(I10:I12) -> 177.76145 | J13: =SUM(J10:J12) -> 196.72538 | ... V13: =SUM(V10:V12) -> 2991.4963
B14: YoY Growth | G14: =+G13/C13-1 -> -0.21904762 | H14: =+H13/D13-1 -> -0.2721202 | I14: =+I13/E13-1 -> 0.2500805 | J14: =+J13/F13-1 -> -0.11504552 | K14: =+K13/G13-1 -> 0.20743391 | L14: =+L13/H13-1 -> 1.2870766 | M14: =+M13/I13-1 -> 1.1186093 | N14: =+N13/J13-1 -> 1.4100612 | ... V14: =+V13/R13-1 -> 1.5118864
B15: Trading Spread (bps)
B16: Spot | C16: =+AVERAGEIFS('Monthly Metrics'!$C26:$T26,'Monthly Metrics'!$C$7:$T$7,'Revenue Build'!C$7,'Monthly Metrics'!$C$6:$T$6,'Revenue Build'!C$6) -> 1.9933333 | D16: =+AVERAGEIFS('Monthly Metrics'!$C26:$T26,'Monthly Metrics'!$C$7:$T$7,'Revenue Build'!D$7,'Monthly Metrics'!$C$6:$T$6,'Revenue Build'!D$6) -> 1.5933333 | E16: =+AVERAGEIFS('Monthly Metrics'!$C26:$T26,'Monthly Metrics'!$C$7:$T$7,'Revenue Build'!E$7,'Monthly Metrics'!$C$6:$T$6,'Revenue Build'!E$6) -> 2.09 | F16: =+AVERAGEIFS('Monthly Metrics'!$C26:$T26,'Monthly Metrics'!$C$7:$T$7,'Revenue Build'!F$7,'Monthly Metrics'!$C$6:$T$6,'Revenue Build'!F$6) -> 1.8366667 | G16: =+AVERAGEIFS('Monthly Metrics'!$C26:$T26,'Monthly Metrics'!$C$7:$T$7,'Revenue Build'!G$7,'Monthly Metrics'!$C$6:$T$6,'Revenue Build'!G$6) -> 1.99 | H16: =+AVERAGEIFS('Monthly Metrics'!$C26:$T26,'Monthly Metrics'!$C$7:$T$7,'Revenue Build'!H$7,'Monthly Metrics'!$C$6:$T$6,'Revenue Build'!H$6) -> 2.43 | I16: =+AVERAGE(C16:H16) * ( 1- $W$16) -> 2.0883333 | J16: =+I16 * (1+$W$16) -> 1.9839167 | K16: =+J16 * (1+$W$16) -> 1.8847208 | L16: =+K16 * (1+$W$16) -> 1.7904848 | M16: =+L16 * (1+$W$16) -> 1.7009606 | N16: =+M16 * (1+$W$16) -> 1.6159125 | O16: =+N16 * (1+$W$16) -> 1.5351169 | P16: =+O16 * (1+$W$16) -> 1.4583611 | Q16: =+P16 * (1+$W$16) -> 1.385443 | ... V16: =+U16 * (1+$W$16) -> 1.0720294 | W16: -0.05 | X16: Taper | Z16: Bullish consistently states that they intend to offer the lowest spreads and high liquidity.
B17: Options | E17: =+AVERAGEIFS('Monthly Metrics'!$C27:$T27,'Monthly Metrics'!$C$7:$T$7,'Revenue Build'!E$7,'Monthly Metrics'!$C$6:$T$6,'Revenue Build'!E$6) -> 0.965 | F17: =+AVERAGEIFS('Monthly Metrics'!$C27:$T27,'Monthly Metrics'!$C$7:$T$7,'Revenue Build'!F$7,'Monthly Metrics'!$C$6:$T$6,'Revenue Build'!F$6) -> 1.43 | G17: =+AVERAGEIFS('Monthly Metrics'!$C27:$T27,'Monthly Metrics'!$C$7:$T$7,'Revenue Build'!G$7,'Monthly Metrics'!$C$6:$T$6,'Revenue Build'!G$6) -> 2.0766667 | H17: =+AVERAGEIFS('Monthly Metrics'!$C27:$T27,'Monthly Metrics'!$C$7:$T$7,'Revenue Build'!H$7,'Monthly Metrics'!$C$6:$T$6,'Revenue Build'!H$6) -> 1.58 | I17: =+AVERAGE(C17:H17) * ( 1- $W$16) -> 1.5885625 | J17: =+I17 * (1+$W$16) -> 1.5091344 | K17: =+J17 * (1+$W$16) -> 1.4336777 | L17: =+K17 * (1+$W$16) -> 1.3619938 | M17: =+L17 * (1+$W$16) -> 1.2938941 | N17: =+M17 * (1+$W$16) -> 1.2291994 | O17: =+N17 * (1+$W$16) -> 1.1677394 | P17: =+O17 * (1+$W$16) -> 1.1093524 | Q17: =+P17 * (1+$W$16) -> 1.0538848 | ... V17: =+U17 * (1+$W$16) -> 0.81547598
B18: Perps | C18: =+AVERAGEIFS('Monthly Metrics'!$C28:$T28,'Monthly Metrics'!$C$7:$T$7,'Revenue Build'!C$7,'Monthly Metrics'!$C$6:$T$6,'Revenue Build'!C$6) -> -1.6166667 | D18: =+AVERAGEIFS('Monthly Metrics'!$C28:$T28,'Monthly Metrics'!$C$7:$T$7,'Revenue Build'!D$7,'Monthly Metrics'!$C$6:$T$6,'Revenue Build'!D$6) -> -1.1833333 | E18: =+AVERAGEIFS('Monthly Metrics'!$C28:$T28,'Monthly Metrics'!$C$7:$T$7,'Revenue Build'!E$7,'Monthly Metrics'!$C$6:$T$6,'Revenue Build'!E$6) -> -0.41333333 | F18: =+AVERAGEIFS('Monthly Metrics'!$C28:$T28,'Monthly Metrics'!$C$7:$T$7,'Revenue Build'!F$7,'Monthly Metrics'!$C$6:$T$6,'Revenue Build'!F$6) -> -1.0333333 | G18: =+AVERAGEIFS('Monthly Metrics'!$C28:$T28,'Monthly Metrics'!$C$7:$T$7,'Revenue Build'!G$7,'Monthly Metrics'!$C$6:$T$6,'Revenue Build'!G$6) -> -0.05 | H18: =+AVERAGEIFS('Monthly Metrics'!$C28:$T28,'Monthly Metrics'!$C$7:$T$7,'Revenue Build'!H$7,'Monthly Metrics'!$C$6:$T$6,'Revenue Build'!H$6) -> -0.11333333 | I18: =+AVERAGE(C18:H18) * ( 1- $W$16) -> -0.77175 | J18: =+I18 * (1+$W$16) -> -0.7331625 | K18: =+J18 * (1+$W$16) -> -0.69650437 | L18: =+K18 * (1+$W$16) -> -0.66167916 | M18: =+L18 * (1+$W$16) -> -0.6285952 | N18: =+M18 * (1+$W$16) -> -0.59716544 | O18: =+N18 * (1+$W$16) -> -0.56730717 | P18: =+O18 * (1+$W$16) -> -0.53894181 | Q18: =+P18 * (1+$W$16) -> -0.51199472 | ... V18: =+U18 * (1+$W$16) -> -0.39617175
B19: Average Trading Spread | C19: =+AVERAGE(C16:C18) -> 0.18833333 | D19: =+AVERAGE(D16:D18) -> 0.205 | E19: =+AVERAGE(E16:E18) -> 0.88055556 | F19: =+AVERAGE(F16:F18) -> 0.74444444 | G19: =+AVERAGE(G16:G18) -> 1.3388889 | H19: =+AVERAGE(H16:H18) -> 1.2988889 | I19: =+AVERAGE(I16:I18) -> 0.96838194 | J19: =+AVERAGE(J16:J18) -> 0.91996285 | ... V19: =+AVERAGE(V16:V18) -> 0.4971112
B20: Spread Revenue ($Ms)
B21: Spot | H21: =+(H10*(H16/10000)) * 1000 -> 27.5805 | I21: =+(I10*(I16/10000)) * 1000 -> 33.325117 | J21: =+(J10*(J16/10000)) * 1000 -> 35.036289 | K21: =+(K10*(K16/10000)) * 1000 -> 40.204048 | L21: =+(L10*(L16/10000)) * 1000 -> 48.083202 | M21: =+(M10*(M16/10000)) * 1000 -> 57.506507 | N21: =+(N10*(N16/10000)) * 1000 -> 68.776583 | O21: =+(O10*(O16/10000)) * 1000 -> 82.255359 | ... V21: =+(V10*(V16/10000)) * 1000 -> 287.89189
B22: Options | H22: =+(H11*(H17/10000)) * 1000 -> 1.3904 | I22: =+(I11*(I17/10000)) * 1000 -> 1.1567403 | J22: =+(J11*(J17/10000)) * 1000 -> 1.2161364 | K22: =+(K11*(K17/10000)) * 1000 -> 1.3955133 | L22: =+(L11*(L17/10000)) * 1000 -> 1.6690048 | M22: =+(M11*(M17/10000)) * 1000 -> 1.9960949 | N22: =+(N11*(N17/10000)) * 1000 -> 2.3872879 | O22: =+(O11*(O17/10000)) * 1000 -> 2.8551465 | ... V22: =+(V11*(V17/10000)) * 1000 -> 9.9929481
B23: Perps | H23: =+(H12*(H18/10000)) * 1000 -> -0.096333333 | I23: =+(I12*(I18/10000)) * 1000 -> -0.8413767 | J23: =+(J12*(J18/10000)) * 1000 -> -0.88457956 | K23: =+(K12*(K18/10000)) * 1000 -> -1.0150527 | L23: =+(L12*(L18/10000)) * 1000 -> -1.2139818 | M23: =+(M12*(M18/10000)) * 1000 -> -1.4518969 | N23: =+(N12*(N18/10000)) * 1000 -> -1.7364384 | O23: =+(O12*(O18/10000)) * 1000 -> -2.0767441 | ... V23: =+(V12*(V18/10000)) * 1000 -> -7.2685575
B24: Total Spread Revenue | H24: =SUM(H21:H23) -> 28.874567 | I24: =SUM(I21:I23) -> 33.640481 | J24: =SUM(J21:J23) -> 35.367846 | K24: =SUM(K21:K23) -> 40.584508 | L24: =SUM(L21:L23) -> 48.538225 | M24: =SUM(M21:M23) -> 58.050705 | N24: =SUM(N21:N23) -> 69.427432 | O24: =SUM(O21:O23) -> 83.033761 | ... V24: =SUM(V21:V23) -> 290.61628
B26: Transaction Income ($Ms) | C26: ='Income Statement'!N35 -> 0.563 | D26: ='Income Statement'!O35 -> 0.4 | E26: ='Income Statement'!P35 -> 0.8 | F26: ='Income Statement'!Q35 -> 1.642 | G26: ='Income Statement'!R35 -> 2.712 | H26: =(H13*1000)*(H27/10000) -> 0.81757431 | I26: =(I13*1000)*(I27/10000) -> 1.2539037 | J26: =(J13*1000)*(J27/10000) -> 1.5776276 | K26: =(K13*1000)*(K27/10000) -> 2.0193567 | L26: =(L13*1000)*(L27/10000) -> 2.6087347 | M26: =(M13*1000)*(M27/10000) -> 2.9030771 | N26: =(N13*1000)*(N27/10000) -> 3.793005 | O26: =(O13*1000)*(O27/10000) -> 4.8880685 | ... V26: =(V13*1000)*(V27/10000) -> 24.323
B27: Take Rate (bps) | C27: =(C26/(C13*1000)) * 10000 -> 0.02234127 | D27: =(D26/(D13*1000)) * 10000 -> 0.022259321 | E27: =(E26/(E13*1000)) * 10000 -> 0.05625879 | F27: =(F26/(F13*1000)) * 10000 -> 0.073864148 | G27: =(G26/(G13*1000)) * 10000 -> 0.13780488 | H27: =AVERAGE(C27:G27) -> 0.062505681 | I27: =AVERAGE(D27:H27) -> 0.070538564 | J27: =AVERAGE(E27:I27) -> 0.080194412 | K27: =AVERAGE(F27:J27) -> 0.084981537 | L27: =AVERAGE(G27:K27) -> 0.087205014 | M27: =AVERAGE(H27:L27) -> 0.077085042 | N27: =AVERAGE(I27:M27) -> 0.080000914 | O27: =AVERAGE(J27:N27) -> 0.081893384 | ... V27: =AVERAGE(Q27:U27) -> 0.081307138
B29: Total Transaction Revenue | H29: =H24+H26 -> 29.692141 | I29: =I24+I26 -> 34.894384 | J29: =J24+J26 -> 36.945474 | K29: =K24+K26 -> 42.603865 | L29: =L24+L26 -> 51.14696 | M29: =M24+M26 -> 60.953782 | N29: =N24+N26 -> 73.220437 | O29: =O24+O26 -> 87.921829 | ... V29: =V24+V26 -> 314.93928
B31: CoinDesk (Data, Insights, Indiies) | G31: =34/4 -> 8.5 | H31: =G31*(1+((1+$C$33)^(1/4)-1)) -> 8.8022436 | I31: =H31*(1+((1+$C$33)^(1/4)-1)) -> 9.1152345 | J31: =I31*(1+((1+$C$33)^(1/4)-1)) -> 9.4393547 | K31: =J31*(1+((1+$C$33)^(1/4)-1)) -> 9.775 | L31: =K31*(1+((1+$C$33)^(1/4)-1)) -> 10.12258 | M31: =L31*(1+((1+$C$33)^(1/4)-1)) -> 10.48252 | N31: =M31*(1+((1+$C$33)^(1/4)-1)) -> 10.855258 | O31: =N31*(1+((1+$C$33)^(1/4)-1)) -> 11.24125 | ... V31: =U31*(1+((1+$C$33)^(1/4)-1)) -> 14.356079 | Z31: CoinDesk (Data [incl. CCData] + Insights + Indices), separated from Conferences, is anchored to a ~$29M FY24 run-rate — built from the acquisition footnotes' pro-forma disclosures (original CoinDesk ~$28–29M standalone + CCData ~$5M, netted for overlap) — then grown at an assumed ~15–20%/yr (midpoint ~17.5%) to arrive at a ~$34M FY2025 estimate, ex-conferences.
B32: Conferences | H32: =18/4 -> 4.5 | I32: =18/4 -> 4.5 | J32: =18/4 -> 4.5 | K32: =18/4 -> 4.5 | L32: =18/4 -> 4.5 | M32: =18/4 -> 4.5 | N32: =18/4 -> 4.5 | O32: =18/4 -> 4.5 | ... V32: =18/4 -> 4.5 | Z32: Two conferences annually, generating $9M based on 2025 Hong Kong Consensus revenue.
B33: CoinDesk Growth Rate | C33: 0.15
B35: Liquidity Services | G35: ='Income Statement'!R41-G31 -> 46.27 | H35: =G35*(1+((1+H36)^(1/4)-1)) -> 51.206172 | I35: =H35*(1+((1+I36)^(1/4)-1)) -> 56.668945 | J35: =I35*(1+((1+J36)^(1/4)-1)) -> 62.714497 | K35: =J35*(1+((1+K36)^(1/4)-1)) -> 72.193078 | L35: =K35*(1+((1+L36)^(1/4)-1)) -> 83.104239 | M35: =L35*(1+((1+M36)^(1/4)-1)) -> 95.664497 | N35: =M35*(1+((1+N36)^(1/4)-1)) -> 110.1231 | O35: =N35*(1+((1+O36)^(1/4)-1)) -> 126.76695 | ... V35: =U35*(1+((1+V36)^(1/4)-1)) -> 339.54657
B36: CoinDesk Annual Growth Rate | H36: =INDEX('Scenario & Sensitivity'!$C$16:$F$18,MATCH(Summary!$C$17,'Scenario & Sensitivity'!$B$16:$B$18,0),MATCH(_xlfn.NUMBERVALUE(RIGHT('Revenue Build'!H$8,4)),'Scenario & Sensitivity'!$C$15:$F$15,0)) -> 0.5 | I36: =INDEX('Scenario & Sensitivity'!$C$16:$F$18,MATCH(Summary!$C$17,'Scenario & Sensitivity'!$B$16:$B$18,0),MATCH(_xlfn.NUMBERVALUE(RIGHT('Revenue Build'!I$8,4)),'Scenario & Sensitivity'!$C$15:$F$15,0)) -> 0.5 | J36: =INDEX('Scenario & Sensitivity'!$C$16:$F$18,MATCH(Summary!$C$17,'Scenario & Sensitivity'!$B$16:$B$18,0),MATCH(_xlfn.NUMBERVALUE(RIGHT('Revenue Build'!J$8,4)),'Scenario & Sensitivity'!$C$15:$F$15,0)) -> 0.5 | K36: =INDEX('Scenario & Sensitivity'!$C$16:$F$18,MATCH(Summary!$C$17,'Scenario & Sensitivity'!$B$16:$B$18,0),MATCH(_xlfn.NUMBERVALUE(RIGHT('Revenue Build'!K$8,4)),'Scenario & Sensitivity'!$C$15:$F$15,0)) -> 0.75594322 | L36: =INDEX('Scenario & Sensitivity'!$C$16:$F$18,MATCH(Summary!$C$17,'Scenario & Sensitivity'!$B$16:$B$18,0),MATCH(_xlfn.NUMBERVALUE(RIGHT('Revenue Build'!L$8,4)),'Scenario & Sensitivity'!$C$15:$F$15,0)) -> 0.75594322 | M36: =INDEX('Scenario & Sensitivity'!$C$16:$F$18,MATCH(Summary!$C$17,'Scenario & Sensitivity'!$B$16:$B$18,0),MATCH(_xlfn.NUMBERVALUE(RIGHT('Revenue Build'!M$8,4)),'Scenario & Sensitivity'!$C$15:$F$15,0)) -> 0.75594322 | N36: =INDEX('Scenario & Sensitivity'!$C$16:$F$18,MATCH(Summary!$C$17,'Scenario & Sensitivity'!$B$16:$B$18,0),MATCH(_xlfn.NUMBERVALUE(RIGHT('Revenue Build'!N$8,4)),'Scenario & Sensitivity'!$C$15:$F$15,0)) -> 0.75594322 | O36: =INDEX('Scenario & Sensitivity'!$C$16:$F$18,MATCH(Summary!$C$17,'Scenario & Sensitivity'!$B$16:$B$18,0),MATCH(_xlfn.NUMBERVALUE(RIGHT('Revenue Build'!O$8,4)),'Scenario & Sensitivity'!$C$15:$F$15,0)) -> 0.75594322 | ... V36: =INDEX('Scenario & Sensitivity'!$C$16:$F$18,MATCH(Summary!$C$17,'Scenario & Sensitivity'!$B$16:$B$18,0),MATCH(_xlfn.NUMBERVALUE(RIGHT('Revenue Build'!V$8,4)),'Scenario & Sensitivity'!$C$15:$F$15,0)) -> 0.75594322
B38: Subscriptions and Services Revenue | H38: =H31+H32+H35 -> 64.508416 | I38: =I31+I32+I35 -> 70.28418 | J38: =J31+J32+J35 -> 76.653852 | K38: =K31+K32+K35 -> 86.468078 | L38: =L31+L32+L35 -> 97.726819 | M38: =M31+M32+M35 -> 110.64702 | N38: =N31+N32+N35 -> 125.47835 | O38: =O31+O32+O35 -> 142.5082 | ... V38: =V31+V32+V35 -> 358.40265

Sheet Scenario & Sensitivity
B2: Scenario & Sensitivity Analysis
B4: SCENARIOS
B6: Transaction Volume Growth | C6: 2026 | D6: =C6+1 -> 2027 | E6: =D6+1 -> 2028 | F6: =E6+1 -> 2029 | H6: Notes
B7: Bull | C7: 0.5 | D7: =$C$12 -> 1.5118864 | E7: =$C$12 -> 1.5118864 | F7: =$C$12 -> 1.5118864 | H7: Based on McKinsey tokenization market growth by 2030 (Including: Bonds, loans, funds and Equities = $2-4T) [Most conservative estimate: https://a16zcrypto.com/posts/article/tokenized-asset-rwa-market-data-charts/]
B8: Base | C8: 0.25 | D8: =D7/2 -> 0.75594322 | E8: =E7/2 -> 0.75594322 | F8: =F7/2 -> 0.75594322 | H8: 50% haircut to Bull
B9: Bear | C9: 0.15 | D9: =C9-0.025 -> 0.125 | E9: =D9-0.025 -> 0.1 | F9: =E9-0.025 -> 0.075 | H9: Taper 2.5%
B11: TAM Growth by 2030 | C11: 100
B12: CAGR | C12: =(C11^(1/5)) -1 -> 1.5118864
B15: Liquidity Service Growth | C15: 2026 | D15: =C15+1 -> 2027 | E15: =D15+1 -> 2028 | F15: =E15+1 -> 2029 | H15: Notes
B16: Bull | C16: 0.5 | D16: =+D7*0.5 -> 0.75594322 | E16: =+E7*0.5 -> 0.75594322 | F16: =+F7*0.5 -> 0.75594322 | H16: Q1'26 runrate already 50%+, without the Equiniti cross sell opps. / Forecasted .5 beta to volume growth rate as this take a sales effort
B17: Base | C17: 0.25 | D17: 0.2 | E17: 0.2 | F17: 0.2 | H17: Management post Equiniti: 20% revenue growth from tokenization and blockchain services
B18: Bear | C18: 0.15 | D18: =C18-0.025 -> 0.125 | E18: =D18-0.025 -> 0.1 | F18: =E18-0.025 -> 0.075 | H18: Taper 2.5%
C20: =LEFT(C21,2) -> Q1 | D20: =LEFT(D21,2) -> Q2 | E20: =LEFT(E21,2) -> Q3 | F20: =LEFT(F21,2) -> Q4 | H20: =LEFT(H21,2) -> Q1
C21: ='Income Statement'!J6 -> Q1 2024 | D21: ='Income Statement'!K6 -> Q2 2024 | E21: ='Income Statement'!L6 -> Q3 2024 | F21: ='Income Statement'!M6 -> Q4 2024 | H21: ='Income Statement'!N6 -> Q1 2025
B22: Subscriptions and services revenue | C22: ='Income Statement'!J41 -> 8.8 | D22: ='Income Statement'!K41 -> 25.8 | E22: ='Income Statement'!L41 -> 11.5 | F22: ='Income Statement'!M41 -> 13.684 | H22: ='Income Statement'!N41 -> 19.741
B23: CoinDesk | C23: =C22-C24-C25 -> 5.3 | D23: =D22-D24-D25 -> 13.3 | E23: =E22-E24-E25 -> 8 | F23: =F22-F24-F25 -> 10.184 | H23: =AVERAGE(C23:F23) -> 9.196
B24: Confrences | D24: =9 -> 9 | H24: =9 -> 9
B25: Liquidity Services | C25: =14/4 -> 3.5 | D25: =14/4 -> 3.5 | E25: =14/4 -> 3.5 | F25: =14/4 -> 3.5

Sheet P&L Inputs >>

Sheet Income Statement
B2: Income Statement - Bullish (BLSH) Standalone
J3: =YEAR(J4) -> 2024 | K3: =YEAR(K4) -> 2024 | L3: =YEAR(L4) -> 2024 | M3: =YEAR(M4) -> 2024 | N3: =YEAR(N4) -> 2025 | O3: =YEAR(O4) -> 2025 | P3: =YEAR(P4) -> 2025 | Q3: =YEAR(Q4) -> 2025 | ... AG3: =YEAR(AG4) -> 2029
J4: 45354 | K4: =EOMONTH(J4,3) -> 45473 | L4: =EOMONTH(K4,3) -> 45565 | M4: =EOMONTH(L4,3) -> 45657 | N4: =EOMONTH(M4,3) -> 45747 | O4: =EOMONTH(N4,3) -> 45838 | P4: =EOMONTH(O4,3) -> 45930 | Q4: =EOMONTH(P4,3) -> 46022 | R4: =EOMONTH(Q4,3) -> 46112 | ... AG4: =EOMONTH(AF4,3) -> 47483
B5: P&L (as reported)
B6: ($mm unless noted) | C6: 2024 | D6: 2025 | E6: 2026 | F6: 2027 | G6: 2028 | H6: 2029 | J6: ="Q" & INT((MONTH(J4)-1)/3)+1 & " " & YEAR(J4) -> Q1 2024 | K6: ="Q" & INT((MONTH(K4)-1)/3)+1 & " " & YEAR(K4) -> Q2 2024 | L6: ="Q" & INT((MONTH(L4)-1)/3)+1 & " " & YEAR(L4) -> Q3 2024 | M6: ="Q" & INT((MONTH(M4)-1)/3)+1 & " " & YEAR(M4) -> Q4 2024 | N6: ="Q" & INT((MONTH(N4)-1)/3)+1 & " " & YEAR(N4) -> Q1 2025 | O6: ="Q" & INT((MONTH(O4)-1)/3)+1 & " " & YEAR(O4) -> Q2 2025 | P6: ="Q" & INT((MONTH(P4)-1)/3)+1 & " " & YEAR(P4) -> Q3 2025 | Q6: ="Q" & INT((MONTH(Q4)-1)/3)+1 & " " & YEAR(Q4) -> Q4 2025 | ... AG6: ="Q" & INT((MONTH(AG4)-1)/3)+1 & " " & YEAR(AG4) -> Q4 2029
B7: Digital assets sales | C7: =SUMIFS($J7:$V7,$J$3:$V$3,C$6) -> 250201.28 | D7: =SUMIFS($J7:$V7,$J$3:$V$3,D$6) -> 244811.39 | E7: =SUMIFS($J7:$V7,$J$3:$V$3,E$6) -> 84397.834 | F7: =SUMIFS($J7:$V7,$J$3:$V$3,F$6) -> 0 | G7: =SUMIFS($J7:$V7,$J$3:$V$3,G$6) -> 0 | H7: =SUMIFS($J7:$V7,$J$3:$V$3,H$6) -> 0 | J7: 80404.577 | K7: 49578.206 | L7: 54192.368 | M7: 66026.131 | N7: 80236.157 | O7: 58630.645 | P7: 41599.507 | Q7: 64345.078 | R7: 51812.747 | S7: 32585.087
B8: Cost of digital assets derecognized | C8: =SUMIFS($J8:$V8,$J$3:$V$3,C$6) -> -250104.77 | D8: =SUMIFS($J8:$V8,$J$3:$V$3,D$6) -> -244733.09 | E8: =SUMIFS($J8:$V8,$J$3:$V$3,E$6) -> -84362.303 | F8: =SUMIFS($J8:$V8,$J$3:$V$3,F$6) -> 0 | G8: =SUMIFS($J8:$V8,$J$3:$V$3,G$6) -> 0 | H8: =SUMIFS($J8:$V8,$J$3:$V$3,H$6) -> 0 | J8: -80375.573 | K8: -49556.478 | L8: -54171.381 | M8: -66001.337 | N8: -80209.641 | O8: -58615.273 | P8: -41584.605 | Q8: -64323.568 | R8: -51792.742 | S8: -32569.561
B9: Other revenues | C9: =SUMIFS($J9:$V9,$J$3:$V$3,C$6) -> 61.968 | D9: =SUMIFS($J9:$V9,$J$3:$V$3,D$6) -> 158.941 | E9: =SUMIFS($J9:$V9,$J$3:$V$3,E$6) -> 122.433 | F9: =SUMIFS($J9:$V9,$J$3:$V$3,F$6) -> 0 | G9: =SUMIFS($J9:$V9,$J$3:$V$3,G$6) -> 0 | H9: =SUMIFS($J9:$V9,$J$3:$V$3,H$6) -> 0 | J9: 9.366 | K9: 26.257 | L9: 11.872 | M9: 14.473 | N9: 20.304 | O9: 32.292 | P9: 50.15 | Q9: 56.195 | R9: 57.482 | S9: 64.951
B10: Change in fair value of digital assets held, net | C10: =SUMIFS($J10:$V10,$J$3:$V$3,C$6) -> 207.043 | D10: =SUMIFS($J10:$V10,$J$3:$V$3,D$6) -> -674.968 | E10: =SUMIFS($J10:$V10,$J$3:$V$3,E$6) -> -804.198 | F10: =SUMIFS($J10:$V10,$J$3:$V$3,F$6) -> 0 | G10: =SUMIFS($J10:$V10,$J$3:$V$3,G$6) -> 0 | H10: =SUMIFS($J10:$V10,$J$3:$V$3,H$6) -> 0 | J10: 162.174 | K10: -99.372 | L10: -41.788 | M10: 186.029 | N10: -246.762 | O10: 68.409 | P10: -11.44 | Q10: -485.175 | R10: -559.584 | S10: -244.614
B11: Net spread related income and change in fair value of perpetual futures on the Exchange | C11: =SUMIFS($J11:$V11,$J$3:$V$3,C$6) -> -17.138 | D11: =SUMIFS($J11:$V11,$J$3:$V$3,D$6) -> -7.179 | E11: =SUMIFS($J11:$V11,$J$3:$V$3,E$6) -> -0.945 | F11: =SUMIFS($J11:$V11,$J$3:$V$3,F$6) -> 0 | G11: =SUMIFS($J11:$V11,$J$3:$V$3,G$6) -> 0 | H11: =SUMIFS($J11:$V11,$J$3:$V$3,H$6) -> 0 | J11: -4.22 | K11: -4.797 | L11: -4.893 | M11: -3.228 | N11: -3.702 | O11: -1.989 | P11: -0.602 | Q11: -0.886 | R11: 0.035 | S11: -0.98
B12: Change in fair value of investment in financial assets | C12: =SUMIFS($J12:$V12,$J$3:$V$3,C$6) -> 29.453 | D12: =SUMIFS($J12:$V12,$J$3:$V$3,D$6) -> -36.035 | E12: =SUMIFS($J12:$V12,$J$3:$V$3,E$6) -> -122.951 | F12: =SUMIFS($J12:$V12,$J$3:$V$3,F$6) -> 0 | G12: =SUMIFS($J12:$V12,$J$3:$V$3,G$6) -> 0 | H12: =SUMIFS($J12:$V12,$J$3:$V$3,H$6) -> 0 | J12: 0.349 | K12: -0.738 | L12: 2.473 | M12: 27.369 | N12: -71.81 | O12: 86.359 | P12: 54.971 | Q12: -105.555 | R12: -92.373 | S12: -30.578
B13: Administrative expenses | C13: =SUMIFS($J13:$V13,$J$3:$V$3,C$6) -> -153.119 | D13: =SUMIFS($J13:$V13,$J$3:$V$3,D$6) -> -182.188 | E13: =SUMIFS($J13:$V13,$J$3:$V$3,E$6) -> -104.548 | F13: =SUMIFS($J13:$V13,$J$3:$V$3,F$6) -> 0 | G13: =SUMIFS($J13:$V13,$J$3:$V$3,G$6) -> 0 | H13: =SUMIFS($J13:$V13,$J$3:$V$3,H$6) -> 0 | J13: -36.757 | K13: -39.662 | L13: -39.618 | M13: -37.082 | N13: -47.186 | O13: -43.017 | P13: -45.709 | Q13: -46.276 | R13: -48.28 | S13: -56.268
B14: Other expenses | C14: =SUMIFS($J14:$V14,$J$3:$V$3,C$6) -> -46.081 | D14: =SUMIFS($J14:$V14,$J$3:$V$3,D$6) -> -60.425 | E14: =SUMIFS($J14:$V14,$J$3:$V$3,E$6) -> -78.043 | F14: =SUMIFS($J14:$V14,$J$3:$V$3,F$6) -> 0 | G14: =SUMIFS($J14:$V14,$J$3:$V$3,G$6) -> 0 | H14: =SUMIFS($J14:$V14,$J$3:$V$3,H$6) -> 0 | J14: -9.916 | K14: -16.72 | L14: -6.81 | M14: -12.635 | N14: -15.063 | O14: -17.362 | P14: -13.608 | Q14: -14.392 | R14: -45.53 | S14: -32.513
B15: Finance expense | C15: =SUMIFS($J15:$V15,$J$3:$V$3,C$6) -> -38.529 | D15: =SUMIFS($J15:$V15,$J$3:$V$3,D$6) -> -52.369 | E15: =SUMIFS($J15:$V15,$J$3:$V$3,E$6) -> -28.547 | F15: =SUMIFS($J15:$V15,$J$3:$V$3,F$6) -> 0 | G15: =SUMIFS($J15:$V15,$J$3:$V$3,G$6) -> 0 | H15: =SUMIFS($J15:$V15,$J$3:$V$3,H$6) -> 0 | J15: -8.929 | K15: -9.063 | L15: -9.878 | M15: -10.659 | N15: -10.24 | O15: -13.291 | P15: -13.906 | Q15: -14.932 | R15: -14.088 | S15: -14.459
B16: Change in fair value of derivatives | C16: =SUMIFS($J16:$V16,$J$3:$V$3,C$6) -> -12.19 | D16: =SUMIFS($J16:$V16,$J$3:$V$3,D$6) -> 9.609 | E16: =SUMIFS($J16:$V16,$J$3:$V$3,E$6) -> 91.58 | F16: =SUMIFS($J16:$V16,$J$3:$V$3,F$6) -> 0 | G16: =SUMIFS($J16:$V16,$J$3:$V$3,G$6) -> 0 | H16: =SUMIFS($J16:$V16,$J$3:$V$3,H$6) -> 0 | J16: -0.526 | K16: 0.175 | L16: 1.028 | M16: -12.867 | N16: 0 | O16: -2.379 | P16: -5.533 | Q16: 17.521 | R16: 69.197 | S16: 22.383
B17: Change in fair value of financial liability at FVTPL | C17: =SUMIFS($J17:$V17,$J$3:$V$3,C$6) -> -43.35 | D17: =SUMIFS($J17:$V17,$J$3:$V$3,D$6) -> -20.1 | E17: =SUMIFS($J17:$V17,$J$3:$V$3,E$6) -> 4.2 | F17: =SUMIFS($J17:$V17,$J$3:$V$3,F$6) -> 0 | G17: =SUMIFS($J17:$V17,$J$3:$V$3,G$6) -> 0 | H17: =SUMIFS($J17:$V17,$J$3:$V$3,H$6) -> 0 | J17: -35.6 | K17: 6.1 | L17: 0.1 | M17: -13.95 | N17: -0.9 | O17: -15.25 | P17: -10.85 | Q17: 6.9 | R17: 8.5 | S17: -4.3
B18: Income/(loss) before income tax | C18: =SUMIFS($J18:$V18,$J$3:$V$3,C$6) -> 84.57 | D18: =SUMIFS($J18:$V18,$J$3:$V$3,D$6) -> -786.414 | E18: =SUMIFS($J18:$V18,$J$3:$V$3,E$6) -> -885.488 | F18: =SUMIFS($J18:$V18,$J$3:$V$3,F$6) -> 0 | G18: =SUMIFS($J18:$V18,$J$3:$V$3,G$6) -> 0 | H18: =SUMIFS($J18:$V18,$J$3:$V$3,H$6) -> 0 | J18: =J7+J8+J9+J10+J11+J12+J13+J14+J15+J16+J17 -> 104.945 | K18: =K7+K8+K9+K10+K11+K12+K13+K14+K15+K16+K17 -> -116.092 | L18: =L7+L8+L9+L10+L11+L12+L13+L14+L15+L16+L17 -> -66.527 | M18: =M7+M8+M9+M10+M11+M12+M13+M14+M15+M16+M17 -> 162.244 | N18: =N7+N8+N9+N10+N11+N12+N13+N14+N15+N16+N17 -> -348.843 | O18: =O7+O8+O9+O10+O11+O12+O13+O14+O15+O16+O17 -> 109.144 | P18: =P7+P8+P9+P10+P11+P12+P13+P14+P15+P16+P17 -> 18.375 | Q18: =Q7+Q8+Q9+Q10+Q11+Q12+Q13+Q14+Q15+Q16+Q17 -> -565.09 | ... AG18: =AG7+AG8+AG9+AG10+AG11+AG12+AG13+AG14+AG15+AG16+AG17 -> 0
B19: Income tax benefit/(expense) | C19: =SUMIFS($J19:$V19,$J$3:$V$3,C$6) -> -5.005 | D19: =SUMIFS($J19:$V19,$J$3:$V$3,D$6) -> 0.502 | E19: =SUMIFS($J19:$V19,$J$3:$V$3,E$6) -> -0.23 | F19: =SUMIFS($J19:$V19,$J$3:$V$3,F$6) -> 0 | G19: =SUMIFS($J19:$V19,$J$3:$V$3,G$6) -> 0 | H19: =SUMIFS($J19:$V19,$J$3:$V$3,H$6) -> 0 | J19: -0.176 | K19: -0.302 | L19: -0.745 | M19: -3.782 | N19: -0.221 | O19: -0.876 | P19: 0.076 | Q19: 1.523 | R19: -0.226 | S19: -0.004
B20: Net income/(loss) (IFRS) | C20: =SUMIFS($J20:$V20,$J$3:$V$3,C$6) -> 79.565 | D20: =SUMIFS($J20:$V20,$J$3:$V$3,D$6) -> -785.912 | E20: =SUMIFS($J20:$V20,$J$3:$V$3,E$6) -> -885.718 | F20: =SUMIFS($J20:$V20,$J$3:$V$3,F$6) -> 0 | G20: =SUMIFS($J20:$V20,$J$3:$V$3,G$6) -> 0 | H20: =SUMIFS($J20:$V20,$J$3:$V$3,H$6) -> 0 | J20: =J18+J19 -> 104.769 | K20: =K18+K19 -> -116.394 | L20: =L18+L19 -> -67.272 | M20: =M18+M19 -> 158.462 | N20: =N18+N19 -> -349.064 | O20: =SUM(O18:O19) -> 108.268 | P20: =P18+P19 -> 18.451 | Q20: =Q18+Q19 -> -563.567 | R20: =R18+R19 -> -604.862 | S20: =S18+S19 -> -280.856 | T20: =T18+T19 -> 0 | U20: =U18+U19 -> 0 | V20: =V18+V19 -> 0 | W20: =W18+W19 -> 0 | ... AG20: =AG18+AG19 -> 0
B22: Memo: Attributable to Owners of the Group | K22: -115.346 | L22: -66.732 | M22: 157.033 | N22: -343.994 | O22: 107.513 | P22: 18.397 | Q22: -546.598 | R22: -581.713
B23: Memo: Attributable to Non-controlling interests | K23: -1.048 | L23: -0.54 | M23: 1.429 | N23: -4.628 | O23: 0.755 | P23: 0.054 | Q23: -16.969 | R23: -23.149
B24: Memo: Weighted avg. shares outstanding - Basic (mm) | K24: 112.5 | L24: 112.5 | M24: 113.153 | N24: 113.215 | O24: 113.215 | P24: 133.066 | Q24: 150.924 | R24: 151.146
B25: Memo: Weighted avg. shares outstanding - Diluted (mm) | K25: 112.5 | L25: 112.5 | M25: 115.889 | N25: 113.215 | O25: 115.951 | P25: 140.157 | Q25: 150.924 | R25: 151.146
B26: Memo: EPS - Basic ($) | K26: -1.03 | L26: -0.59 | M26: 1.4 | N26: -3.04 | O26: 0.95 | P26: 0.14 | Q26: -3.73 | R26: -3.85
B27: Memo: EPS - Diluted ($) | K27: -1.03 | L27: -0.59 | M27: 1.37 | N27: -3.04 | O27: 0.93 | P27: 0.1 | Q27: -3.73 | R27: -3.85
B29: BLOCK 2 - BRIDGE: DIGITAL ASSETS SALES -> ADJUSTED TRANSACTION REVENUE
B30: Digital assets sales | J30: =J7 -> 80404.577 | K30: =K7 -> 49578.206 | L30: =L7 -> 54192.368 | M30: =M7 -> 66026.131 | N30: =N7 -> 80236.157 | O30: =O7 -> 58630.645 | P30: =P7 -> 41599.507 | Q30: =Q7 -> 64345.078 | ... AG30: =AG7 -> 0
B31: (-) Digital asset sales on venues other than Exchange | C31: =SUMIFS($J31:$V31,$J$3:$V$3,C$6) -> -21.824 | D31: =SUMIFS($J31:$V31,$J$3:$V$3,D$6) -> -396.446 | E31: =SUMIFS($J31:$V31,$J$3:$V$3,E$6) -> 0 | F31: =SUMIFS($J31:$V31,$J$3:$V$3,F$6) -> 0 | G31: =SUMIFS($J31:$V31,$J$3:$V$3,G$6) -> 0 | H31: =SUMIFS($J31:$V31,$J$3:$V$3,H$6) -> 0 | J31: =-14.5-K31 -> -5.7 | K31: -8.8 | L31: -5.2 | M31: -2.124 | N31: -303.863 | O31: -30.1 | P31: -25.9 | Q31: -36.583 | R31: 0 | S31: 0
B32: Digital asset sales - on our Exchange (subtotal) | C32: =SUMIFS($J32:$V32,$J$3:$V$3,C$6) -> 250179.46 | D32: =SUMIFS($J32:$V32,$J$3:$V$3,D$6) -> 244414.94 | E32: =SUMIFS($J32:$V32,$J$3:$V$3,E$6) -> 84397.834 | F32: =SUMIFS($J32:$V32,$J$3:$V$3,F$6) -> 0 | G32: =SUMIFS($J32:$V32,$J$3:$V$3,G$6) -> 0 | H32: =SUMIFS($J32:$V32,$J$3:$V$3,H$6) -> 0 | J32: =J30+J31 -> 80398.877 | K32: =K30+K31 -> 49569.406 | L32: =L30+L31 -> 54187.168 | M32: =M30+M31 -> 66024.007 | N32: =N30+N31 -> 79932.294 | O32: =O30+O31 -> 58600.545 | P32: =P30+P31 -> 41573.607 | Q32: =Q30+Q31 -> 64308.495 | ... AG32: =AG30+AG31 -> 0
B33: Cost of digital assets derecognized | C33: =SUMIFS($J33:$V33,$J$3:$V$3,C$6) -> -250082.93 | D33: =SUMIFS($J33:$V33,$J$3:$V$3,D$6) -> -244336.49 | E33: =SUMIFS($J33:$V33,$J$3:$V$3,E$6) -> -84362.303 | F33: =SUMIFS($J33:$V33,$J$3:$V$3,F$6) -> 0 | G33: =SUMIFS($J33:$V33,$J$3:$V$3,G$6) -> 0 | H33: =SUMIFS($J33:$V33,$J$3:$V$3,H$6) -> 0 | J33: =-129917.5-K33 -> -80369.9 | K33: =-49547.6 -> -49547.6 | L33: =-54166.2 -> -54166.2 | M33: =-65999.234 -> -65999.234 | N33: =-138490.9-O33 -> -79905.8 | O33: =-58585.1 -> -58585.1 | P33: =-41558.6 -> -41558.6 | Q33: =-64286.992 -> -64286.992 | R33: =R8 -> -51792.742 | S33: =S8 -> -32569.561
B34: (+) Change in FV of digital asset inventories, arising from purchase on our Exchange | C34: =SUMIFS($J34:$V34,$J$3:$V$3,C$6) -> 71.662 | D34: =SUMIFS($J34:$V34,$J$3:$V$3,D$6) -> 56.058 | E34: =SUMIFS($J34:$V34,$J$3:$V$3,E$6) -> 27.472 | F34: =SUMIFS($J34:$V34,$J$3:$V$3,F$6) -> 0 | G34: =SUMIFS($J34:$V34,$J$3:$V$3,G$6) -> 0 | H34: =SUMIFS($J34:$V34,$J$3:$V$3,H$6) -> 0 | J34: =36.6 -K34 -> 19.1 | K34: 17.5 | L34: 16.4 | M34: 18.662 | N34: 18.688 | O34: 10.2 | P34: 11.5 | Q34: 15.67 | R34: 15.265 | S34: =27.472-R34 -> 12.207
B35: (+) Transaction income | C35: =SUMIFS($J35:$V35,$J$3:$V$3,C$6) -> 2.189 | D35: =SUMIFS($J35:$V35,$J$3:$V$3,D$6) -> 3.405 | E35: =SUMIFS($J35:$V35,$J$3:$V$3,E$6) -> 4.974 | F35: =SUMIFS($J35:$V35,$J$3:$V$3,F$6) -> 0 | G35: =SUMIFS($J35:$V35,$J$3:$V$3,G$6) -> 0 | H35: =SUMIFS($J35:$V35,$J$3:$V$3,H$6) -> 0 | J35: =1-K35 -> 0.6 | K35: 0.4 | L35: 0.4 | M35: 0.789 | N35: 0.563 | O35: 0.4 | P35: 0.8 | Q35: 1.642 | R35: 2.712 | S35: =4.974-R35 -> 2.262
B36: (+) Net spread related income and change in FV of perpetual futures | C36: =SUMIFS($J36:$V36,$J$3:$V$3,C$6) -> -17.121 | D36: =SUMIFS($J36:$V36,$J$3:$V$3,D$6) -> -7.179 | E36: =SUMIFS($J36:$V36,$J$3:$V$3,E$6) -> -0.945 | F36: =SUMIFS($J36:$V36,$J$3:$V$3,F$6) -> 0 | G36: =SUMIFS($J36:$V36,$J$3:$V$3,G$6) -> 0 | H36: =SUMIFS($J36:$V36,$J$3:$V$3,H$6) -> 0 | J36: =-9-K36 -> -4.203 | K36: =K11 -> -4.797 | L36: =L11 -> -4.893 | M36: =M11 -> -3.228 | N36: =N11 -> -3.702 | O36: =O11 -> -1.989 | P36: =P11 -> -0.602 | Q36: =Q11 -> -0.886 | R36: =R11 -> 0.035 | ... AG36: =AG11 -> 0
B37: Adjusted Transaction Revenue | C37: =SUMIFS($J37:$AG37,$J$3:$AG$3,C$6) -> 153.254 | D37: =SUMIFS($J37:$AG37,$J$3:$AG$3,D$6) -> 130.733 | E37: =SUMIFS($J37:$AG37,$J$3:$AG$3,E$6) -> 139.549 | F37: =SUMIFS($J37:$AG37,$J$3:$AG$3,F$6) -> 227.92504 | G37: =SUMIFS($J37:$AG37,$J$3:$AG$3,G$6) -> 471.54494 | H37: =SUMIFS($J37:$AG37,$J$3:$AG$3,H$6) -> 977.9252 | J37: =SUM(J32:J36) -> 44.474 | K37: =SUM(K32:K36) -> 34.909 | L37: =SUM(L32:L36) -> 32.875 | M37: =SUM(M32:M36) -> 40.996 | N37: =SUM(N32:N36) -> 42.043 | O37: =SUM(O32:O36) -> 24.056 | P37: =SUM(P32:P36) -> 26.705 | Q37: =SUM(Q32:Q36) -> 37.929 | R37: =SUM(R32:R36) -> 38.017 | S37: ='Revenue Build'!H29 -> 29.692141 | T37: ='Revenue Build'!I29 -> 34.894384 | U37: ='Revenue Build'!J29 -> 36.945474 | V37: ='Revenue Build'!K29 -> 42.603865 | W37: ='Revenue Build'!L29 -> 51.14696 | X37: ='Revenue Build'!M29 -> 60.953782 | Y37: ='Revenue Build'!N29 -> 73.220437 | Z37: ='Revenue Build'!O29 -> 87.921829 | ... AG37: ='Revenue Build'!V29 -> 314.93928
B39: BLOCK 3 - BRIDGE: ADJUSTED TRANSACTION REVENUE -> ADJUSTED REVENUE
B40: Adjusted Transaction Revenue | C40: =C37 -> 153.254 | D40: =D37 -> 130.733 | E40: =E37 -> 139.549 | F40: =F37 -> 227.92504 | G40: =G37 -> 471.54494 | H40: =H37 -> 977.9252 | J40: =J37 -> 44.474 | K40: =K37 -> 34.909 | L40: =L37 -> 32.875 | M40: =M37 -> 40.996 | N40: =N37 -> 42.043 | O40: =O37 -> 24.056 | P40: =P37 -> 26.705 | Q40: =Q37 -> 37.929 | ... AG40: =AG37 -> 314.93928
B41: (+) Subscriptions and services revenue | C41: =SUMIFS($J41:$AG41,$J$3:$AG$3,C$6) -> 59.784 | D41: =SUMIFS($J41:$AG41,$J$3:$AG$3,D$6) -> 155.495 | E41: =SUMIFS($J41:$AG41,$J$3:$AG$3,E$6) -> 264.39703 | F41: =SUMIFS($J41:$AG41,$J$3:$AG$3,F$6) -> 420.32027 | G41: =SUMIFS($J41:$AG41,$J$3:$AG$3,G$6) -> 699.46526 | H41: =SUMIFS($J41:$AG41,$J$3:$AG$3,H$6) -> 1185.8801 | J41: =34.6-K41 -> 8.8 | K41: 25.8 | L41: 11.5 | M41: 13.684 | N41: 19.741 | O41: 31.9 | P41: 49.3 | Q41: 54.554 | R41: 54.77 | S41: =117.459-R41 -> 62.689 | T41: ='Revenue Build'!I38 -> 70.28418 | U41: ='Revenue Build'!J38 -> 76.653852 | V41: ='Revenue Build'!K38 -> 86.468078 | W41: ='Revenue Build'!L38 -> 97.726819 | X41: ='Revenue Build'!M38 -> 110.64702 | Y41: ='Revenue Build'!N38 -> 125.47835 | Z41: ='Revenue Build'!O38 -> 142.5082 | AA41: ='Revenue Build'!P38 -> 162.06729 | ... AG41: ='Revenue Build'!V38 -> 358.40265
B42: (+) Change in FV of investment in financial assets (pre-2024 only) | C42: =SUMIFS($J42:$AG42,$J$3:$AG$3,C$6) -> 0.2 | D42: =SUMIFS($J42:$AG42,$J$3:$AG$3,D$6) -> 0 | E42: =SUMIFS($J42:$AG42,$J$3:$AG$3,E$6) -> 0 | F42: =SUMIFS($J42:$AG42,$J$3:$AG$3,F$6) -> 0 | G42: =SUMIFS($J42:$AG42,$J$3:$AG$3,G$6) -> 0 | H42: =SUMIFS($J42:$AG42,$J$3:$AG$3,H$6) -> 0 | J42: =0.2 -K42 -> 0.2 | K42: 0 | L42: 0 | M42: 0 | N42: 0 | O42: 0 | P42: 0 | Q42: 0 | R42: 0 | S42: 0
B43: (+) Revaluation of digital assets held as investments | C43: =SUMIFS($J43:$AG43,$J$3:$AG$3,C$6) -> 0.703 | D43: =SUMIFS($J43:$AG43,$J$3:$AG$3,D$6) -> 2.168 | E43: =SUMIFS($J43:$AG43,$J$3:$AG$3,E$6) -> 0.089 | F43: =SUMIFS($J43:$AG43,$J$3:$AG$3,F$6) -> 0 | G43: =SUMIFS($J43:$AG43,$J$3:$AG$3,G$6) -> 0 | H43: =SUMIFS($J43:$AG43,$J$3:$AG$3,H$6) -> 0 | K43: 0 | L43: 0.2 | M43: 0.503 | N43: 0.643 | O43: 1 | P43: 0.5 | Q43: 0.025 | R43: 0.039 | S43: 0.05
B44: Adjusted Revenue | C44: =SUM(C40:C43) -> 213.941 | D44: =SUM(D40:D43) -> 288.396 | E44: =SUM(E40:E43) -> 404.03503 | F44: =SUM(F40:F43) -> 648.24531 | G44: =SUM(G40:G43) -> 1171.0102 | H44: =SUM(H40:H43) -> 2163.8053 | J44: =SUM(J40:J43) -> 53.474 | K44: =K40+K41+K42+K43 -> 60.709 | L44: =L40+L41+L42+L43 -> 44.575 | M44: =M40+M41+M42+M43 -> 55.183 | N44: =N40+N41+N42+N43 -> 62.427 | O44: =O40+O41+O42+O43 -> 56.956 | P44: =P40+P41+P42+P43 -> 76.505 | Q44: =Q40+Q41+Q42+Q43 -> 92.508 | R44: =R40+R41+R42+R43 -> 92.826 | ... AG44: =AG40+AG41+AG42+AG43 -> 673.34193
...

Sheet Balance Sheet
B2: Balance Sheet - Bullish (BLSH) Standalone, IFRS Basis
B3: Quarterly figures as reported in each Form 6-K / earnings release (Q2'25, Q3'25, Q4'25, Q1'26 releases) and Dec-24 comparative. 1Q24-3Q24 and 1Q25 point-in-time balance sheets were not disclosed in the sourced documents and are left blank rather than estimated. Annual (FY) columns show the year-end (4Q) snapshot, not a sum, since the Balance Sheet is a point-in-time statement - unlike the Income Statement and Cash Flow tabs. No pro forma / Equiniti effects included anywhere on this tab.
J5: =YEAR(J6) -> 2024 | K5: =YEAR(K6) -> 2024 | L5: =YEAR(L6) -> 2024 | M5: =YEAR(M6) -> 2024 | N5: =YEAR(N6) -> 2025 | O5: =YEAR(O6) -> 2025 | P5: =YEAR(P6) -> 2025 | Q5: =YEAR(Q6) -> 2025 | ... V5: =YEAR(V6) -> 2027
J6: 45354 | K6: =EOMONTH(J6,3) -> 45473 | L6: =EOMONTH(K6,3) -> 45565 | M6: =EOMONTH(L6,3) -> 45657 | N6: =EOMONTH(M6,3) -> 45747 | O6: =EOMONTH(N6,3) -> 45838 | P6: =EOMONTH(O6,3) -> 45930 | Q6: =EOMONTH(P6,3) -> 46022 | R6: =EOMONTH(Q6,3) -> 46112 | ... V6: =EOMONTH(U6,3) -> 46477
B7: QUARTERLY BALANCE SHEET, WITH YEAR-END (4Q) SNAPSHOT IN ANNUAL COLUMNS
B8: ($000s unless noted) | C8: 2024 | D8: 2025 | E8: =D8+1 -> 2026 | F8: =E8+1 -> 2027 | G8: =F8+1 -> 2028 | H8: =G8+1 -> 2029 | J8: 1Q24A | K8: 2Q24A | L8: 3Q24A | M8: 4Q24A | N8: 1Q25A | O8: 2Q25A | P8: 3Q25A | Q8: 4Q25A | R8: 1Q26A | S8: 2Q26P | T8: 3Q26P | U8: 4Q26P | V8: 1Q27P
B9: ASSETS
B10: Non-current assets
B11: Goodwill | C11: =IF(M11="","",M11) -> 61475 | D11: =IF(Q11="","",Q11) -> 63062 | E11: =IF(U11="","",U11) | M11: 61475 | O11: 63458 | P11: 63023 | Q11: 63062 | R11: 62682 | S11: 62648
B12: Other intangible assets | C12: =IF(M12="","",M12) -> 33298 | D12: =IF(Q12="","",Q12) -> 31104 | E12: =IF(U12="","",U12) | M12: 33298 | O12: 32232 | P12: 31661 | Q12: 31104 | R12: 30535 | S12: 29978
B13: Property and equipment and right-of-use assets | C13: =IF(M13="","",M13) -> 14118 | D13: =IF(Q13="","",Q13) -> 28369 | E13: =IF(U13="","",U13) | M13: 14118 | O13: 14856 | P13: 12206 | Q13: 28369 | R13: 26465 | S13: 27541
B14: Deferred tax assets | C14: =IF(M14="","",M14) -> 2088 | D14: =IF(Q14="","",Q14) -> 2865 | E14: =IF(U14="","",U14) | M14: 2088 | O14: 2519 | P14: 2894 | Q14: 2865 | R14: 2995 | S14: 2823
B15: Other assets (non-current) | C15: =IF(M15="","",M15) -> 22087 | D15: =IF(Q15="","",Q15) -> 21311 | E15: =IF(U15="","",U15) | M15: 22087 | O15: 20583 | P15: 22237 | Q15: 21311 | R15: 17662 | S15: 26074
B16: Restricted cash (non-current) | C16: =IF(M16="","",M16) -> 1968 | D16: =IF(Q16="","",Q16) -> 5727 | E16: =IF(U16="","",U16) | M16: 1968 | O16: 1968 | P16: 1968 | Q16: 5727 | R16: 5840 | S16: 5817
B17: Total non-current assets | C17: =IF(M17="","",M17) -> 135034 | D17: =IF(Q17="","",Q17) -> 152438 | E17: =IF(U17="","",U17) -> 0 | J17: =J11+J12+J13+J14+J15+J16 -> 0 | K17: =K11+K12+K13+K14+K15+K16 -> 0 | L17: =L11+L12+L13+L14+L15+L16 -> 0 | M17: =M11+M12+M13+M14+M15+M16 -> 135034 | N17: =N11+N12+N13+N14+N15+N16 -> 0 | O17: =O11+O12+O13+O14+O15+O16 -> 135616 | P17: =P11+P12+P13+P14+P15+P16 -> 133989 | Q17: =Q11+Q12+Q13+Q14+Q15+Q16 -> 152438 | ... V17: =V11+V12+V13+V14+V15+V16 -> 0
B19: Current assets
B20: Digital assets held - inventories | C20: =IF(M20="","",M20) -> 573876 | D20: =IF(Q20="","",Q20) -> 206178 | E20: =IF(U20="","",U20) | M20: 573876 | O20: 231870 | P20: 254203 | Q20: 206178 | R20: 142698 | S20: 139131
B21: Digital assets held - intangible assets | C21: =IF(M21="","",M21) -> 1878268 | D21: =IF(Q21="","",Q21) -> 1537071 | E21: =IF(U21="","",U21) | M21: 1878268 | O21: 1957402 | P21: 2094385 | Q21: 1537071 | R21: 1298611 | S21: 1133596
B22: Digital assets held - financial assets | C22: =IF(M22="","",M22) -> 132649 | D22: =IF(Q22="","",Q22) -> 1037915 | E22: =IF(U22="","",U22) | M22: 132649 | O22: 106020 | P22: 1189097 | Q22: 1037915 | R22: 863306 | S22: 952626
B23: Loan and other receivables - digital assets | C23: =IF(M23="","",M23) -> 166388 | D23: =IF(Q23="","",Q23) -> 446481 | E23: =IF(U23="","",U23) | M23: 166388 | O23: 310927 | P23: 436720 | Q23: 446481 | R23: 395684 | S23: 269111
B24: Derivative financial instruments | C24: =IF(M24="","",M24) -> 0 | D24: =IF(Q24="","",Q24) -> 0 | E24: =IF(U24="","",U24) | M24: 0 | O24: 181 | P24: 20 | Q24: 0 | R24: 6298 | S24: 0
B25: Investments in financial assets | C25: =IF(M25="","",M25) -> 86173 | D25: =IF(Q25="","",Q25) -> 404144 | E25: =IF(U25="","",U25) | M25: 86173 | O25: 422470 | P25: 375845 | Q25: 404144 | R25: 266640 | S25: 226237
B26: Other assets (current) | C26: =IF(M26="","",M26) -> 21209 | D26: =IF(Q26="","",Q26) -> 47502 | E26: =IF(U26="","",U26) | M26: 21209 | O26: 19133 | P26: 38590 | Q26: 47502 | R26: 55945 | S26: 64687
B27: Customer segregated cash | C27: =IF(M27="","",M27) -> 6382 | D27: =IF(Q27="","",Q27) -> 20044 | E27: =IF(U27="","",U27) | M27: 6382 | O27: 4138 | P27: 14550 | Q27: 20044 | R27: 55640 | S27: 52724
B28: Restricted cash (current) | C28: =IF(M28="","",M28) -> 15893 | D28: =IF(Q28="","",Q28) -> 16839 | E28: =IF(U28="","",U28) | M28: 15893 | O28: 16193 | P28: 16676 | Q28: 16839 | R28: 17003 | S28: 17106
B29: Cash and cash equivalents | C29: =IF(M29="","",M29) -> 31540 | D29: =IF(Q29="","",Q29) -> 87892 | E29: =IF(U29="","",U29) | M29: 31540 | O29: 35560 | P29: 69307 | Q29: 87892 | R29: 76052 | S29: 86614
