Workbook

Sheet Guide
B1: PubMatic, Inc. (NASDAQ: PUBM) Financial Model
B2: Quarterly history Q1 2023 to Q2 2026, annual roll-up FY2023 to FY2025, forecast infrastructure Q3 2026 to Q4 2028. All figures in $ thousands unless noted.
B4: HOW TO USE
B5: 1. Go to Drivers | C5: Enter your assumptions in the yellow cells (columns P to Y, Q3 2026 to Q4 2028). They are placeholders today so the model runs; nothing is a recommendation.
B6: 2. Read the statements | C6: Income Statement, Balance Sheet and Cash Flow update automatically. Forecast columns have teal headers; actual columns have navy headers. Annual columns are on the right.
B7: 3. Check the Checks tab | C7: B8 should read ALL CHECKS PASS. The balance sheet balances by construction, and history ties to filings.
B8: 4. Use Summary | C8: One page of annual figures for FY2023A to FY2028E.
B10: COLOR LEGEND
B11: Blue text | C11: Hardcoded input (historical figures from filings, or your forecast assumptions)
B12: Black text | C12: Formula on the same sheet
B13: Green text | C13: Link to another sheet
B14: Yellow fill | C14: Forecast input cell for you to edit (Drivers tab)
B16: TABS
B17: Summary | C17: Annual snapshot FY2023A to FY2028E.
B18: Drivers | C18: All forecast assumptions in one place, with the same metric shown historically for context. Column AH explains how each driver is used.
B19: Income Statement | C19: Quarterly and annual P&L, growth and margin analysis, Adjusted EBITDA reconciliation, SBC and D&A memo lines.
B20: Balance Sheet | C20: Quarter-end balance sheet from Q4 2023, with working capital metrics. Annual columns show year-end balances.
B21: Cash Flow | C21: Full cash flow statement by quarter, derived from year-to-date filings for history, and free cash flow.
B22: CF YTD Inputs | C22: Cash flow statement as filed (year-to-date). Feeds the quarterly Cash Flow tab. Includes tie-out to reported totals.
B23: 10-K Data | C23: FY2023 to FY2025 as reported in the FY2025 10-K. Used to derive Q4 and to tie out annual totals.
B24: Checks | C24: Balance sheet, cash, net income, Adjusted EBITDA and annual tie-outs.
B25: Comps | C25: Q2 2026 and 6M 2026 benchmarking vs Magnite, The Trade Desk, Criteo and AppLovin, with infrastructure intensity and hosting model (owned vs cloud).
B27: FORECAST MECHANICS
B28: Revenue and expenses | C28: Each line = same quarter last year x (1 + YoY growth). This preserves the strong Q4 seasonality without a separate seasonal factor.
B29: Below the line | C29: Interest income = prior quarter cash and securities x yield / 4. Taxes = pretax income x effective rate. EPS = net income / diluted shares.
B30: Balance sheet | C30: AR = days sales outstanding x revenue; AP = days payable outstanding x revenue; accrued liabilities = accrued days x opex (all on days in the quarter). PP&E rolls forward with capex, capitalized software and D&A. Leases, goodwill, deferred taxes and other items are held flat.
B31: Cash flow | C31: Net income + D&A + SBC + working capital changes, less capex and capitalized software, less buybacks, plus option/ESPP proceeds. Cash is the plug that ties the balance sheet.
B32: Adjusted EBITDA | C32: Company definition: net income + SBC + D&A + litigation-related expenses - interest income + income taxes. Other income (expense), including FX, is not added back.
B34: SOURCES
B35: FY2025 Form 10-K | C35: Filed Feb 26, 2026. FY2023 to FY2025 income statement, cash flow, SBC by line, Adjusted EBITDA, 12/31/25 and 12/31/24 balance sheets, impressions processed.
B36: Form 10-Q | C36: Q2 2026 10-Q (filed Aug 6, 2026) also supplies the Q2 26 Adjusted EBITDA reconciliation and litigation add-back.
B37: 8-K earnings releases | C37: Q1, Q2, Q3 2024 (2023 and 2024 quarters and balance sheets), Q1, Q2, Q3 2025 (2025 quarters and balance sheets). Exhibit 99.1 on sec.gov.
B38: Form 10-Q | C38: Q1 2026 (filed May 2026) and Q2 2026 (filed Aug 6, 2026).
B39: Q4 figures | C39: Not filed separately. Q4 = full year (10-K) less the first three quarters, for every income statement, SBC and cash flow line.
B41: KNOWN LIMITATIONS AND FLAGS
B42: Balance sheet history | C42: Quarter-end balance sheets for Q1 to Q3 2023 are not included. History starts at Q4 2023.
B43: Q4 diluted shares | C43: Q4 2023, Q4 2024 and Q4 2025 diluted share counts come from a third-party data provider, not a filing. Q4 EPS is the only line affected. Q4 basic shares are approximated (4 x FY less Q1 to Q3).
B44: Q4 basic shares | C44: Q4 basic share counts are approximated as 4 x FY weighted average less Q1 to Q3, since quarterly figures are not reported separately in the 10-K.
B45: Placeholders | C45: Every yellow driver value is a placeholder, not a forecast recommendation.
B46: Operating items held at zero | C46: Deferred taxes, non-cash lease expense, accretion and lease liability changes are not forecast. Leases are held flat.

Sheet Summary
A1: PubMatic, Inc. (NASDAQ: PUBM): Annual Summary
A2: $ in thousands except per share. FY2026E combines two reported quarters (Q1, Q2) and two forecast quarters. Links to the annual roll-up columns on each statement.
A4: Fiscal year | B4: FY2023A | C4: FY2024A | D4: FY2025A | E4: FY2026E | F4: FY2027E | G4: FY2028E
A5: Status | B5: Actual | C5: Actual | D5: Actual | E5: 2A + 2E | F5: Forecast | G5: Forecast
A7: Income statement
A8: Revenue | B8: ='Income Statement'!AB9 -> 267014 | C8: ='Income Statement'!AC9 -> 291256 | D8: ='Income Statement'!AD9 -> 282926 | E8: ='Income Statement'!AE9 -> 330474.04 | F8: ='Income Statement'!AF9 -> 426616.98 | G8: ='Income Statement'!AG9 -> 529545.56
A9: Growth, YoY % | C9: ='Income Statement'!AC35 -> 0.090789247 | D9: ='Income Statement'!AD35 -> -0.028600269 | E9: ='Income Statement'!AE35 -> 0.16805821 | F9: ='Income Statement'!AF35 -> 0.29092434 | G9: ='Income Statement'!AG35 -> 0.24126696
A10: Gross profit | B10: ='Income Statement'!AB11 -> 167785 | C10: ='Income Statement'!AC11 -> 190229 | D10: ='Income Statement'!AD11 -> 179841 | E10: ='Income Statement'!AE11 -> 209309.37 | F10: ='Income Statement'!AF11 -> 275454.08 | G10: ='Income Statement'!AG11 -> 349301.05
A11: Gross margin % | B11: ='Income Statement'!AB12 -> 0.62837529 | C11: ='Income Statement'!AC12 -> 0.65313333 | D11: ='Income Statement'!AD12 -> 0.63564678 | E11: ='Income Statement'!AE12 -> 0.63336102 | F11: ='Income Statement'!AF12 -> 0.64567069 | G11: ='Income Statement'!AG12 -> 0.65962417
A12: Total operating expenses | B12: ='Income Statement'!AB17 -> 165749 | C12: ='Income Statement'!AC17 -> 186302 | D12: ='Income Statement'!AD17 -> 197100 | E12: ='Income Statement'!AE17 -> 204620.32 | F12: ='Income Statement'!AF17 -> 212469.69 | G12: ='Income Statement'!AG17 -> 220622.98
A13: Operating income (loss) | B13: ='Income Statement'!AB18 -> 2036 | C13: ='Income Statement'!AC18 -> 3927 | D13: ='Income Statement'!AD18 -> -17259 | E13: ='Income Statement'!AE18 -> 4689.0549 | F13: ='Income Statement'!AF18 -> 62984.386 | G13: ='Income Statement'!AG18 -> 128678.07
A14: Operating margin % | B14: ='Income Statement'!AB19 -> 0.0076250683 | C14: ='Income Statement'!AC19 -> 0.013482984 | D14: ='Income Statement'!AD19 -> -0.061001817 | E14: ='Income Statement'!AE19 -> 0.014188875 | F14: ='Income Statement'!AF19 -> 0.14763685 | G14: ='Income Statement'!AG19 -> 0.24299717
A15: Net income (loss) | B15: ='Income Statement'!AB27 -> 8881 | C15: ='Income Statement'!AC27 -> 12504 | D15: ='Income Statement'!AD27 -> -14462 | E15: ='Income Statement'!AE27 -> 3347.4791 | F15: ='Income Statement'!AF27 -> 54328.641 | G15: ='Income Statement'!AG27 -> 109146.42
A16: EPS, GAAP diluted ($) | B16: ='Income Statement'!AB32 -> 0.15851286 | C16: ='Income Statement'!AC32 -> 0.23030169 | D16: ='Income Statement'!AD32 -> -0.30764976 | E16: ='Income Statement'!AE32 -> 0.072206972 | F16: ='Income Statement'!AF32 -> 1.1783421 | G16: ='Income Statement'!AG32 -> 2.3672933
A17: Non-GAAP and cash flow
A18: Adjusted EBITDA | B18: ='Income Statement'!AB51 -> 75309 | C18: ='Income Statement'!AC51 -> 92325 | D18: ='Income Statement'!AD51 -> 61640 | E18: ='Income Statement'!AE51 -> 86075.854 | F18: ='Income Statement'!AF51 -> 163239.38 | G18: ='Income Statement'!AG51 -> 253121.28
A19: Adjusted EBITDA margin % | B19: ='Income Statement'!AB52 -> 0.28204139 | C19: ='Income Statement'!AC52 -> 0.31698918 | D19: ='Income Statement'!AD52 -> 0.21786616 | E19: ='Income Statement'!AE52 -> 0.26046177 | F19: ='Income Statement'!AF52 -> 0.38263685 | G19: ='Income Statement'!AG52 -> 0.47799717
A20: Stock-based compensation | B20: ='Income Statement'!AB59 -> 28862 | C20: ='Income Statement'!AC59 -> 37676 | D20: ='Income Statement'!AD59 -> 38378 | E20: ='Income Statement'!AE59 -> 37659.544 | F20: ='Income Statement'!AF59 -> 46927.868 | G20: ='Income Statement'!AG59 -> 58250.011
A21: Depreciation and amortization | B21: ='Income Statement'!AB62 -> 44770 | C21: ='Income Statement'!AC62 -> 45352 | D21: ='Income Statement'!AD62 -> 43769 | E21: ='Income Statement'!AE62 -> 43659.255 | F21: ='Income Statement'!AF62 -> 53327.122 | G21: ='Income Statement'!AG62 -> 66193.195
A22: Net cash from operating activities | B22: ='Cash Flow'!AA23 -> 81121 | C22: ='Cash Flow'!AB23 -> 73425 | D22: ='Cash Flow'!AC23 -> 81059 | E22: ='Cash Flow'!AD23 -> 76321.101 | F22: ='Cash Flow'!AE23 -> 151152.96 | G22: ='Cash Flow'!AF23 -> 229315.7
A23: Free cash flow | B23: ='Cash Flow'!AA50 -> 52833 | C23: ='Cash Flow'!AB50 -> 34897 | D23: ='Cash Flow'!AC50 -> 46203 | E23: ='Cash Flow'!AD50 -> 46184.101 | F23: ='Cash Flow'!AE50 -> 117152.96 | G23: ='Cash Flow'!AF50 -> 195315.7
A24: Free cash flow margin % | B24: ='Cash Flow'!AA51 -> 0.19786603 | C24: ='Cash Flow'!AB51 -> 0.11981556 | D24: ='Cash Flow'!AC51 -> 0.16330419 | E24: ='Cash Flow'!AD51 -> 0.13975107 | F24: ='Cash Flow'!AE51 -> 0.27460924 | G24: ='Cash Flow'!AF51 -> 0.36883645
A25: Share repurchases (cash outflow) | B25: ='Cash Flow'!AA40 -> -59268 | C25: ='Cash Flow'!AB40 -> -75332 | D25: ='Cash Flow'!AC40 -> -46498 | E25: ='Cash Flow'!AD40 -> -50500 | F25: ='Cash Flow'!AE40 -> -40000 | G25: ='Cash Flow'!AF40 -> -40000
A26: Balance sheet (year-end)
A27: Cash and marketable securities | B27: ='Balance Sheet'!AB45 -> 175344 | C27: ='Balance Sheet'!AC45 -> 140587 | D27: ='Balance Sheet'!AD45 -> 145518 | E27: ='Balance Sheet'!AE45 -> 141323.1 | F27: ='Balance Sheet'!AF45 -> 222476.06 | G27: ='Balance Sheet'!AG45 -> 381791.77
A28: Accounts receivable, net | B28: ='Balance Sheet'!AB11 -> 375468 | C28: ='Balance Sheet'!AC11 -> 424814 | D28: ='Balance Sheet'!AD11 -> 358240 | E28: ='Balance Sheet'!AE11 -> 448506.54 | F28: ='Balance Sheet'!AF11 -> 559598.03 | G28: ='Balance Sheet'!AG11 -> 692744.28
A29: Accounts payable | B29: ='Balance Sheet'!AB23 -> 347673 | C29: ='Balance Sheet'!AC23 -> 386602 | D29: ='Balance Sheet'!AD23 -> 343619 | E29: ='Balance Sheet'!AE23 -> 430553.23 | F29: ='Balance Sheet'!AF23 -> 537197.82 | G29: ='Balance Sheet'!AG23 -> 665014.34
A30: Total stockholders' equity | B30: ='Balance Sheet'!AB35 -> 296199 | C30: ='Balance Sheet'!AC35 -> 277263 | D30: ='Balance Sheet'!AD35 -> 262589 | E30: ='Balance Sheet'!AE35 -> 258612.02 | F30: ='Balance Sheet'!AF35 -> 323868.53 | G30: ='Balance Sheet'!AG35 -> 455264.97

Sheet Drivers
A1: Drivers: forecast assumptions
A2: Yellow cells with blue text are your forecast inputs (Q3 2026 to Q4 2028). All values are PLACEHOLDERS to keep the model running; replace them with your own view. History (black) shows the same metric for reference.
A4: Period | B4: Q1'23 | C4: Q2'23 | D4: Q3'23 | E4: Q4'23 | F4: Q1'24 | G4: Q2'24 | H4: Q3'24 | I4: Q4'24 | J4: Q1'25 | K4: Q2'25 | L4: Q3'25 | M4: Q4'25 | N4: Q1'26 | O4: Q2'26 | P4: Q3'26 | Q4: Q4'26 | R4: Q1'27 | S4: Q2'27 | T4: Q3'27 | U4: Q4'27 | V4: Q1'28 | W4: Q2'28 | X4: Q3'28 | Y4: Q4'28 | AA4: FY2023A | AB4: FY2024A | AC4: FY2025A | AD4: FY2026E | AE4: FY2027E | AF4: FY2028E | AH4: How this driver is used
A5: Period end | B5: 45016 | C5: 45107 | D5: 45199 | E5: 45291 | F5: 45382 | G5: 45473 | H5: 45565 | I5: 45657 | J5: 45747 | K5: 45838 | L5: 45930 | M5: 46022 | N5: 46112 | O5: 46203 | P5: 46295 | Q5: 46387 | R5: 46477 | S5: 46568 | T5: 46660 | U5: 46752 | V5: 46843 | W5: 46934 | X5: 47026 | Y5: 47118 | AA5: 45291 | AB5: 45657 | AC5: 46022 | AD5: 46387 | AE5: 46752 | AF5: 47118
A6: Status | B6: Actual | C6: Actual | D6: Actual | E6: Actual | F6: Actual | G6: Actual | H6: Actual | I6: Actual | J6: Actual | K6: Actual | L6: Actual | M6: Actual | N6: Actual | O6: Actual | P6: Forecast | Q6: Forecast | R6: Forecast | S6: Forecast | T6: Forecast | U6: Forecast | V6: Forecast | W6: Forecast | X6: Forecast | Y6: Forecast | AA6: Actual | AB6: Actual | AC6: Actual | AD6: 2A + 2E | AE6: Forecast | AF6: Forecast
A8: Revenue and expense growth (forecast: enter YoY growth vs the same quarter last year)
A9: Revenue growth, YoY % | F9: ='Income Statement'!G9/'Income Statement'!C9-1 -> 0.20383706 | G9: ='Income Statement'!H9/'Income Statement'!D9-1 -> 0.06216643 | H9: ='Income Statement'!I9/'Income Statement'!E9-1 -> 0.12734582 | I9: ='Income Statement'!J9/'Income Statement'!F9-1 -> 0.010661939 | J9: ='Income Statement'!K9/'Income Statement'!G9-1 -> -0.043117794 | K9: ='Income Statement'!L9/'Income Statement'!H9-1 -> 0.056907548 | L9: ='Income Statement'!M9/'Income Statement'!I9-1 -> -0.0532973 | M9: ='Income Statement'!N9/'Income Statement'!J9-1 -> -0.063811373 | ... O9: ='Income Statement'!P9/'Income Statement'!L9-1 -> 0.10546452 | P9: 0.1 | Q9: 0.1 | R9: 0.1 | S9: 0.1 | T9: 0.1 | U9: 0.1 | V9: 0.1 | W9: 0.1 | X9: 0.1 | Y9: 0.1 | AB9: ='Income Statement'!AC35 -> 0.090789247 | AC9: ='Income Statement'!AD35 -> -0.028600269 | AD9: ='Income Statement'!AE35 -> 0.16805821 | AE9: ='Income Statement'!AF35 -> 0.29092434 | AF9: ='Income Statement'!AG35 -> 0.24126696 | AH9: Forecast revenue = same quarter last year x (1 + growth). This keeps seasonality (Q4 is the peak quarter). Recent actuals: Q1 26 -2%, Q2 26 +11%. Placeholder 10%.
A10: Cost of revenue growth, YoY % | F10: ='Income Statement'!G10/'Income Statement'!C10-1 -> 0.065415078 | G10: ='Income Statement'!H10/'Income Statement'!D10-1 -> 0.003710057 | H10: ='Income Statement'!I10/'Income Statement'!E10-1 -> -0.02234487 | I10: ='Income Statement'!J10/'Income Statement'!F10-1 -> 0.030031395 | J10: ='Income Statement'!K10/'Income Statement'!G10-1 -> 0.0064505979 | K10: ='Income Statement'!L10/'Income Statement'!H10-1 -> 0.057710652 | L10: ='Income Statement'!M10/'Income Statement'!I10-1 -> -0.0041163557 | M10: ='Income Statement'!N10/'Income Statement'!J10-1 -> 0.021937036 | ... O10: ='Income Statement'!P10/'Income Statement'!L10-1 -> -0.027619119 | P10: 0.03 | Q10: 0.03 | R10: 0.03 | S10: 0.03 | T10: 0.03 | U10: 0.03 | V10: 0.03 | W10: 0.03 | X10: 0.03 | Y10: 0.03 | AB10: ='Income Statement'!AC10/'Income Statement'!AB10-1 -> 0.018119703 | AC10: ='Income Statement'!AD10/'Income Statement'!AC10-1 -> 0.020370792 | AD10: ='Income Statement'!AE10/'Income Statement'!AD10-1 -> 0.17538597 | AE10: ='Income Statement'!AF10/'Income Statement'!AE10-1 -> 0.24758238 | AF10: ='Income Statement'!AG10/'Income Statement'!AF10-1 -> 0.19238592 | AH10: Cost of revenue is largely fixed (data centers, D&A of platform). Modeled as YoY growth rather than % of revenue. Placeholder 3%.
A11: Technology and development growth, YoY % | F11: ='Income Statement'!G14/'Income Statement'!C14-1 -> 0.2214209 | G11: ='Income Statement'!H14/'Income Statement'!D14-1 -> 0.28662704 | H11: ='Income Statement'!I14/'Income Statement'!E14-1 -> 0.32845945 | I11: ='Income Statement'!J14/'Income Statement'!F14-1 -> 0.14387964 | J11: ='Income Statement'!K14/'Income Statement'!G14-1 -> 0.10201005 | K11: ='Income Statement'!L14/'Income Statement'!H14-1 -> 0.052777457 | L11: ='Income Statement'!M14/'Income Statement'!I14-1 -> 0.091115398 | M11: ='Income Statement'!N14/'Income Statement'!J14-1 -> -0.19346188 | ... O11: ='Income Statement'!P14/'Income Statement'!L14-1 -> 0.0035103115 | P11: 0.03 | Q11: 0.03 | R11: 0.03 | S11: 0.03 | T11: 0.03 | U11: 0.03 | V11: 0.03 | W11: 0.03 | X11: 0.03 | Y11: 0.03 | AB11: ='Income Statement'!AC14/'Income Statement'!AB14-1 -> 0.24454671 | AC11: ='Income Statement'!AD14/'Income Statement'!AC14-1 -> 0.016745333 | AD11: ='Income Statement'!AE14/'Income Statement'!AD14-1 -> -0.0081620343 | AE11: ='Income Statement'!AF14/'Income Statement'!AE14-1 -> 0.03 | AF11: ='Income Statement'!AG14/'Income Statement'!AF14-1 -> 0.03 | AH11: Same-quarter YoY growth. Placeholder 3%.
A12: Sales and marketing growth, YoY % | F12: ='Income Statement'!G15/'Income Statement'!C15-1 -> 0.072988282 | G12: ='Income Statement'!H15/'Income Statement'!D15-1 -> 0.16582534 | H12: ='Income Statement'!I15/'Income Statement'!E15-1 -> 0.21436991 | I12: ='Income Statement'!J15/'Income Statement'!F15-1 -> 0.16754287 | J12: ='Income Statement'!K15/'Income Statement'!G15-1 -> 0.079951642 | K12: ='Income Statement'!L15/'Income Statement'!H15-1 -> 0.09114527 | L12: ='Income Statement'!M15/'Income Statement'!I15-1 -> 0.085921675 | M12: ='Income Statement'!N15/'Income Statement'!J15-1 -> 0.060850903 | ... O12: ='Income Statement'!P15/'Income Statement'!L15-1 -> 0.036904762 | P12: 0.04 | Q12: 0.04 | R12: 0.04 | S12: 0.04 | T12: 0.04 | U12: 0.04 | V12: 0.04 | W12: 0.04 | X12: 0.04 | Y12: 0.04 | AB12: ='Income Statement'!AC15/'Income Statement'!AB15-1 -> 0.15175779 | AC12: ='Income Statement'!AD15/'Income Statement'!AC15-1 -> 0.079386383 | AD12: ='Income Statement'!AE15/'Income Statement'!AD15-1 -> 0.049870216 | AE12: ='Income Statement'!AF15/'Income Statement'!AE15-1 -> 0.04 | AF12: ='Income Statement'!AG15/'Income Statement'!AF15-1 -> 0.04 | AH12: Same-quarter YoY growth. Placeholder 4%.
A13: General and administrative growth, YoY % | F13: ='Income Statement'!G16/'Income Statement'!C16-1 -> 0.11573338 | G13: ='Income Statement'!H16/'Income Statement'!D16-1 -> -0.23964575 | H13: ='Income Statement'!I16/'Income Statement'!E16-1 -> 0.26011657 | I13: ='Income Statement'!J16/'Income Statement'!F16-1 -> 0.10884194 | J13: ='Income Statement'!K16/'Income Statement'!G16-1 -> 0.038639766 | K13: ='Income Statement'!L16/'Income Statement'!H16-1 -> 0.089970707 | L13: ='Income Statement'!M16/'Income Statement'!I16-1 -> 0.032641734 | M13: ='Income Statement'!N16/'Income Statement'!J16-1 -> 0.024274928 | ... O13: ='Income Statement'!P16/'Income Statement'!L16-1 -> 0.078768876 | P13: 0.04 | Q13: 0.04 | R13: 0.04 | S13: 0.04 | T13: 0.04 | U13: 0.04 | V13: 0.04 | W13: 0.04 | X13: 0.04 | Y13: 0.04 | AB13: ='Income Statement'!AC16/'Income Statement'!AB16-1 -> 0.02580978 | AC13: ='Income Statement'!AD16/'Income Statement'!AC16-1 -> 0.046297902 | AD13: ='Income Statement'!AE16/'Income Statement'!AD16-1 -> 0.044128605 | AE13: ='Income Statement'!AF16/'Income Statement'!AE16-1 -> 0.04 | AF13: ='Income Statement'!AG16/'Income Statement'!AF16-1 -> 0.04 | AH13: Same-quarter YoY growth. Placeholder 4%.
A15: Non-cash items, other income and taxes
A16: Depreciation and amortization, % of revenue | B16: ='Income Statement'!C62/'Income Statement'!C9 -> 0.20632772 | C16: ='Income Statement'!D62/'Income Statement'!D9 -> 0.17208274 | D16: ='Income Statement'!E62/'Income Statement'!E9 -> 0.17904424 | E16: ='Income Statement'!F62/'Income Statement'!F9 -> 0.13048463 | F16: ='Income Statement'!G62/'Income Statement'!G9 -> 0.16809343 | G16: ='Income Statement'!H62/'Income Statement'!H9 -> 0.16852246 | H16: ='Income Statement'!I62/'Income Statement'!I9 -> 0.15856852 | I16: ='Income Statement'!J62/'Income Statement'!J9 -> 0.13357582 | ... O16: ='Income Statement'!P62/'Income Statement'!P9 -> 0.12732686 | P16: 0.125 | Q16: 0.125 | R16: 0.125 | S16: 0.125 | T16: 0.125 | U16: 0.125 | V16: 0.125 | W16: 0.125 | X16: 0.125 | Y16: 0.125 | AA16: ='Income Statement'!AB62/'Income Statement'!AB9 -> 0.16766911 | AB16: ='Income Statement'!AC62/'Income Statement'!AC9 -> 0.15571181 | AC16: ='Income Statement'!AD62/'Income Statement'!AD9 -> 0.15470123 | AD16: ='Income Statement'!AE62/'Income Statement'!AE9 -> 0.132111 | AE16: ='Income Statement'!AF62/'Income Statement'!AF9 -> 0.125 | AF16: ='Income Statement'!AG62/'Income Statement'!AG9 -> 0.125 | AH16: Total D&A (embedded in cost of revenue and opex) as % of revenue. Feeds Adjusted EBITDA, cash flow and PP&E roll-forward. Q2 26 actual 12.7%. Placeholder 12.5%.
A17: Stock-based compensation, % of revenue | B17: ='Income Statement'!C59/'Income Statement'!C9 -> 0.12740267 | C17: ='Income Statement'!D59/'Income Statement'!D9 -> 0.11473235 | D17: ='Income Statement'!E59/'Income Statement'!E9 -> 0.11307065 | E17: ='Income Statement'!F59/'Income Statement'!F9 -> 0.086725768 | F17: ='Income Statement'!G59/'Income Statement'!G9 -> 0.13659465 | G17: ='Income Statement'!H59/'Income Statement'!H9 -> 0.1441866 | H17: ='Income Statement'!I59/'Income Statement'!I9 -> 0.13173878 | I17: ='Income Statement'!J59/'Income Statement'!J9 -> 0.11004421 | ... O17: ='Income Statement'!P59/'Income Statement'!P9 -> 0.10620539 | P17: 0.11 | Q17: 0.11 | R17: 0.11 | S17: 0.11 | T17: 0.11 | U17: 0.11 | V17: 0.11 | W17: 0.11 | X17: 0.11 | Y17: 0.11 | AA17: ='Income Statement'!AB59/'Income Statement'!AB9 -> 0.10809171 | AB17: ='Income Statement'!AC59/'Income Statement'!AC9 -> 0.12935699 | AC17: ='Income Statement'!AD59/'Income Statement'!AD9 -> 0.13564678 | AD17: ='Income Statement'!AE59/'Income Statement'!AE9 -> 0.11395614 | AE17: ='Income Statement'!AF59/'Income Statement'!AF9 -> 0.11 | AF17: ='Income Statement'!AG59/'Income Statement'!AG9 -> 0.11 | AH17: Total SBC as % of revenue. Feeds Adjusted EBITDA, cash flow and APIC. Q2 26 actual 10.6%. Placeholder 11%.
A18: Litigation-related add-back to Adjusted EBITDA ($000s) | B18: ='Income Statement'!C48 -> 0 | C18: ='Income Statement'!D48 -> 0 | D18: ='Income Statement'!E48 -> 0 | E18: ='Income Statement'!F48 -> 0 | F18: ='Income Statement'!G48 -> 0 | G18: ='Income Statement'!H48 -> 0 | H18: ='Income Statement'!I48 -> 0 | I18: ='Income Statement'!J48 -> 0 | ... O18: ='Income Statement'!P48 -> 594 | P18: 0 | Q18: 0 | R18: 0 | S18: 0 | T18: 0 | U18: 0 | V18: 0 | W18: 0 | X18: 0 | Y18: 0 | AA18: =SUM(B18:E18) -> 0 | AB18: =SUM(F18:I18) -> 0 | AC18: =SUM(J18:M18) -> 902 | AD18: =SUM(N18:Q18) -> 1032 | AE18: =SUM(R18:U18) -> 0 | AF18: =SUM(V18:Y18) -> 0 | AH18: Litigation-related expenses added back in company-defined Adjusted EBITDA. Placeholder 0.
A19: Interest yield on prior-quarter cash + securities (annualized %) | F19: ='Income Statement'!G21*4/('Balance Sheet'!F9+'Balance Sheet'!F10) -> 0.058490738 | G19: ='Income Statement'!H21*4/('Balance Sheet'!G9+'Balance Sheet'!G10) -> 0.053768073 | H19: ='Income Statement'!I21*4/('Balance Sheet'!H9+'Balance Sheet'!H10) -> 0.047561535 | I19: ='Income Statement'!J21*4/('Balance Sheet'!I9+'Balance Sheet'!I10) -> 0.045705493 | J19: ='Income Statement'!K21*4/('Balance Sheet'!J9+'Balance Sheet'!J10) -> 0.045324248 | K19: ='Income Statement'!L21*4/('Balance Sheet'!K9+'Balance Sheet'!K10) -> 0.038272067 | L19: ='Income Statement'!M21*4/('Balance Sheet'!L9+'Balance Sheet'!L10) -> 0.04076043 | M19: ='Income Statement'!N21*4/('Balance Sheet'!M9+'Balance Sheet'!M10) -> 0.037642441 | ... O19: ='Income Statement'!P21*4/('Balance Sheet'!O9+'Balance Sheet'!O10) -> 0.033490709 | P19: 0.033 | Q19: 0.033 | R19: 0.033 | S19: 0.033 | T19: 0.033 | U19: 0.033 | V19: 0.033 | W19: 0.033 | X19: 0.033 | Y19: 0.033 | AH19: Interest income = prior quarter-end (cash + marketable securities) x yield / 4. Uses prior period balance to avoid circularity. Q2 26 actual about 3.3%.
A20: Other income (expense), net ($000s) | B20: ='Income Statement'!C22 -> -465 | C20: ='Income Statement'!D22 -> -221 | D20: ='Income Statement'!E22 -> 210 | E20: ='Income Statement'!F22 -> 117 | F20: ='Income Statement'!G22 -> 258 | G20: ='Income Statement'!H22 -> 4028 | H20: ='Income Statement'!I22 -> -930 | I20: ='Income Statement'!J22 -> 2014 | ... O20: ='Income Statement'!P22 -> 89 | P20: 0 | Q20: 0 | R20: 0 | S20: 0 | T20: 0 | U20: 0 | V20: 0 | W20: 0 | X20: 0 | Y20: 0 | AA20: =SUM(B20:E20) -> -359 | AB20: =SUM(F20:I20) -> 5370 | AC20: =SUM(J20:M20) -> -4150 | AD20: =SUM(N20:Q20) -> -964 | AE20: =SUM(R20:U20) -> 0 | AF20: =SUM(V20:Y20) -> 0 | AH20: Other income (expense), mainly FX. Placeholder 0.
A21: Effective tax rate % | B21: ='Income Statement'!C26 -> 0.36502271 | C21: ='Income Statement'!D26 -> -0.10523267 | D21: ='Income Statement'!E26 -> 0.058885942 | E21: ='Income Statement'!F26 -> 0.18845737 | F21: ='Income Statement'!G26 -> 0.092119867 | G21: ='Income Statement'!H26 -> 0.17289131 | H21: ='Income Statement'!I26 -> -1.797546 | I21: ='Income Statement'!J26 -> 0.24543974 | ... O21: ='Income Statement'!P26 -> 1.6390218 | P21: 0.21 | Q21: 0.21 | R21: 0.21 | S21: 0.21 | T21: 0.21 | U21: 0.21 | V21: 0.21 | W21: 0.21 | X21: 0.21 | Y21: 0.21 | AA21: ='Income Statement'!AB26 -> 0.15459305 | AB21: ='Income Statement'!AC26 -> 0.29650051 | AC21: ='Income Statement'!AD26 -> 0.093518867 | AD21: ='Income Statement'!AE26 -> 0.5997886 | AE21: ='Income Statement'!AF26 -> 0.21 | AF21: ='Income Statement'!AG26 -> 0.21 | AH21: Tax provision = pretax income x rate. Reported quarterly rates are volatile (Q2 26 was 164% on small pretax income). Placeholder 21%.
A22: Weighted-average diluted shares (000s) | B22: ='Income Statement'!C31 -> 52740 | C22: ='Income Statement'!D31 -> 52029 | D22: ='Income Statement'!E31 -> 55979 | E22: ='Income Statement'!F31 -> 54940 | F22: ='Income Statement'!G31 -> 50039 | G22: ='Income Statement'!H31 -> 55577 | H22: ='Income Statement'!I31 -> 49056 | I22: ='Income Statement'!J31 -> 52620 | ... O22: ='Income Statement'!P31 -> 46106 | P22: 46106 | Q22: 46106 | R22: 46106 | S22: 46106 | T22: 46106 | U22: 46106 | V22: 46106 | W22: 46106 | X22: 46106 | Y22: 46106 | AH22: Weighted-average diluted shares used for forecast EPS. Placeholder holds Q2 26 flat; lower it to reflect buybacks.
A24: Working capital and balance sheet
A25: Days sales outstanding (AR / quarterly revenue x days) | E25: ='Balance Sheet'!F41 -> 408.31035 | F25: ='Balance Sheet'!G41 -> 413.76957 | G25: ='Balance Sheet'!H41 -> 475.63318 | H25: ='Balance Sheet'!I41 -> 482.88914 | I25: ='Balance Sheet'!J41 -> 457.09911 | J25: ='Balance Sheet'!K41 -> 492.30035 | K25: ='Balance Sheet'!L41 -> 490.74721 | L25: ='Balance Sheet'!M41 -> 490.85303 | ... O25: ='Balance Sheet'!P41 -> 443.68999 | P25: 491.3 | Q25: 412.2 | R25: 484.2 | S25: 444.1 | T25: 491.3 | U25: 412.2 | V25: 489.6 | W25: 444.1 | X25: 491.3 | Y25: 412.2 | AH25: Accounts receivable = DSO / days in quarter x quarterly revenue. AR reflects gross billings while revenue is net, so DSO is well above a typical 30-90 days. Placeholder = same quarter last year (seasonal).
A26: Days payable outstanding (AP / quarterly revenue x days) | E26: ='Balance Sheet'!F42 -> 378.08411 | F26: ='Balance Sheet'!G42 -> 394.52206 | G26: ='Balance Sheet'!H42 -> 461.03086 | H26: ='Balance Sheet'!I42 -> 462.26328 | I26: ='Balance Sheet'!J42 -> 415.98306 | J26: ='Balance Sheet'!K42 -> 456.32573 | K26: ='Balance Sheet'!L42 -> 462.54419 | L26: ='Balance Sheet'!M42 -> 482.56545 | ... O26: ='Balance Sheet'!P42 -> 451.6202 | P26: 481.5 | Q26: 395.7 | R26: 493.9 | S26: 453 | T26: 481.5 | U26: 395.7 | V26: 499.4 | W26: 453 | X26: 481.5 | Y26: 395.7 | AH26: Accounts payable (mostly publisher payables) = DPO / days in quarter x quarterly revenue. Measured on net revenue so it is directly comparable to DSO (DSO less DPO = net float). Placeholder = same quarter last year.
A27: Prepaid expenses and other current assets ($000s) | E27: ='Balance Sheet'!F12 -> 11143 | F27: ='Balance Sheet'!G12 -> 11540 | G27: ='Balance Sheet'!H12 -> 14788 | H27: ='Balance Sheet'!I12 -> 12640 | I27: ='Balance Sheet'!J12 -> 10145 | J27: ='Balance Sheet'!K12 -> 12018 | K27: ='Balance Sheet'!L12 -> 11994 | L27: ='Balance Sheet'!M12 -> 21307 | ... O27: ='Balance Sheet'!P12 -> 17162 | P27: 17162 | Q27: 17162 | R27: 17162 | S27: 17162 | T27: 17162 | U27: 17162 | V27: 17162 | W27: 17162 | X27: 17162 | Y27: 17162 | AH27: Balance held flat at Q2 26 level. Overwrite with your own balance.
A28: Accrued liabilities days (accrued / quarterly opex x days) | E28: ='Balance Sheet'!F44 -> 59.10423 | F28: ='Balance Sheet'!G44 -> 38.426413 | G28: ='Balance Sheet'!H44 -> 44.520741 | H28: ='Balance Sheet'!I44 -> 49.621644 | I28: ='Balance Sheet'!J44 -> 53.000765 | J28: ='Balance Sheet'!K44 -> 36.454128 | K28: ='Balance Sheet'!L44 -> 38.23188 | L28: ='Balance Sheet'!M44 -> 46.232815 | ... O28: ='Balance Sheet'!P44 -> 42.291079 | P28: 46 | Q28: 50.6 | R28: 32.4 | S28: 41.9 | T28: 46 | U28: 50.6 | V28: 32.8 | W28: 41.9 | X28: 46 | Y28: 50.6 | AH28: Accrued liabilities = accrued days / days in quarter x quarterly operating expenses (includes seasonal bonus accruals). Placeholder = same quarter last year.
A29: Marketable securities balance ($000s) | E29: ='Balance Sheet'!F10 -> 96835 | F29: ='Balance Sheet'!G10 -> 93887 | G29: ='Balance Sheet'!H10 -> 92075 | H29: ='Balance Sheet'!I10 -> 61463 | I29: ='Balance Sheet'!J10 -> 40135 | J29: ='Balance Sheet'!K10 -> 42315 | K29: ='Balance Sheet'!L10 -> 27089 | L29: ='Balance Sheet'!M10 -> 0 | ... O29: ='Balance Sheet'!P10 -> 17536 | P29: 17536 | Q29: 17536 | R29: 17536 | S29: 17536 | T29: 17536 | U29: 17536 | V29: 17536 | W29: 17536 | X29: 17536 | Y29: 17536 | AH29: Marketable securities balance held flat. Changes flow through investing cash flow.
A31: Capital expenditures and capital allocation ($000s, enter as positive numbers)
A32: Purchases of property and equipment | B32: =-'Cash Flow'!B26 -> 1417 | C32: =-'Cash Flow'!C26 -> 1135 | D32: =-'Cash Flow'!D26 -> 2872 | E32: =-'Cash Flow'!E26 -> 5177 | F32: =-'Cash Flow'!F26 -> 801 | G32: =-'Cash Flow'!G26 -> 736 | H32: =-'Cash Flow'!H26 -> 11731 | I32: =-'Cash Flow'!I26 -> 4324 | ... O32: =-'Cash Flow'!O26 -> 2955 | P32: 3500 | Q32: 3500 | R32: 3500 | S32: 3500 | T32: 3500 | U32: 3500 | V32: 3500 | W32: 3500 | X32: 3500 | Y32: 3500 | AA32: =SUM(B32:E32) -> 10601 | AB32: =SUM(F32:I32) -> 17592 | AC32: =SUM(J32:M32) -> 14345 | AD32: =SUM(N32:Q32) -> 9966 | AE32: =SUM(R32:U32) -> 14000 | AF32: =SUM(V32:Y32) -> 14000 | AH32: Cash purchases of PP&E. Q1 26 and Q2 26 actuals were $0.0M and $3.0M. Placeholder $3.5M per quarter.
A33: Capitalized software development costs | B33: =-'Cash Flow'!B27 -> 6001 | C33: =-'Cash Flow'!C27 -> 3918 | D33: =-'Cash Flow'!D27 -> 3806 | E33: =-'Cash Flow'!E27 -> 3962 | F33: =-'Cash Flow'!F27 -> 7231 | G33: =-'Cash Flow'!G27 -> 4295 | H33: =-'Cash Flow'!H27 -> 4542 | I33: =-'Cash Flow'!I27 -> 4868 | ... O33: =-'Cash Flow'!O27 -> 3592 | P33: 5000 | Q33: 5000 | R33: 5000 | S33: 5000 | T33: 5000 | U33: 5000 | V33: 5000 | W33: 5000 | X33: 5000 | Y33: 5000 | AA33: =SUM(B33:E33) -> 17687 | AB33: =SUM(F33:I33) -> 20936 | AC33: =SUM(J33:M33) -> 20511 | AD33: =SUM(N33:Q33) -> 20171 | AE33: =SUM(R33:U33) -> 20000 | AF33: =SUM(V33:Y33) -> 20000 | AH33: Cash capitalized internal-use software. Recent run rate about $5M per quarter. Placeholder $5.0M.
A34: Amortization of acquisition-related intangibles (included in D&A) | P34: 395 | Q34: 395 | R34: 281 | S34: 281 | T34: 281 | U34: 281 | V34: 0 | W34: 0 | X34: 0 | Y34: 0 | AD34: =SUM(N34:Q34) -> 790 | AE34: =SUM(R34:U34) -> 1124 | AF34: =SUM(V34:Y34) -> 0 | AH34: Intangible amortization per the Q2 26 10-Q schedule: $790K for the rest of 2026, $1,124K in 2027, then nil. Included in total D&A.
A35: Share repurchases | B35: =-'Cash Flow'!B40 -> 7898 | C35: =-'Cash Flow'!C40 -> 15582 | D35: =-'Cash Flow'!D40 -> 17999 | E35: =-'Cash Flow'!E40 -> 17789 | F35: =-'Cash Flow'!F40 -> 17500 | G35: =-'Cash Flow'!G40 -> 18368 | H35: =-'Cash Flow'!H40 -> 29532 | I35: =-'Cash Flow'!I40 -> 9932 | ... O35: =-'Cash Flow'!O40 -> 22000 | P35: 10000 | Q35: 10000 | R35: 10000 | S35: 10000 | T35: 10000 | U35: 10000 | V35: 10000 | W35: 10000 | X35: 10000 | Y35: 10000 | AA35: =SUM(B35:E35) -> 59268 | AB35: =SUM(F35:I35) -> 75332 | AC35: =SUM(J35:M35) -> 46498 | AD35: =SUM(N35:Q35) -> 50500 | AE35: =SUM(R35:U35) -> 40000 | AF35: =SUM(V35:Y35) -> 40000 | AH35: Cash spent on repurchases. $63.6M of authorization remained at 6/30/26 and the program expires 12/31/26 unless extended. Placeholder $10M per quarter assumes an extension.
A36: Proceeds from option exercises and ESPP | B36: ='Cash Flow'!B38+'Cash Flow'!B37 -> 314 | C36: ='Cash Flow'!C38+'Cash Flow'!C37 -> 1594 | D36: ='Cash Flow'!D38+'Cash Flow'!D37 -> 273 | E36: ='Cash Flow'!E38+'Cash Flow'!E37 -> 1237 | F36: ='Cash Flow'!F38+'Cash Flow'!F37 -> 939 | G36: ='Cash Flow'!G38+'Cash Flow'!G37 -> 1786 | H36: ='Cash Flow'!H38+'Cash Flow'!H37 -> 304 | I36: ='Cash Flow'!I38+'Cash Flow'!I37 -> 1104 | ... O36: ='Cash Flow'!O38+'Cash Flow'!O37 -> 1461 | P36: 1000 | Q36: 1000 | R36: 1000 | S36: 1000 | T36: 1000 | U36: 1000 | V36: 1000 | W36: 1000 | X36: 1000 | Y36: 1000 | AA36: =SUM(B36:E36) -> 3418 | AB36: =SUM(F36:I36) -> 4133 | AC36: =SUM(J36:M36) -> 3907 | AD36: =SUM(N36:Q36) -> 3938 | AE36: =SUM(R36:U36) -> 4000 | AF36: =SUM(V36:Y36) -> 4000 | AH36: Proceeds from option exercises and ESPP. H1 26 actual about $1.9M. Placeholder $1M per quarter.
A38: Revenue Drivers
A39: Impressions processed (trillions) | F39: 57.9 | G39: 60.7 | H39: 69.8 | I39: 74.7 | J39: 74.7 | K39: 77.7 | L39: 86.8 | M39: 97.6 | N39: 94 | O39: 92 | P39: =+L39*(1+P40) -> 109.40767 | Q39: =+M39*(1+Q40) -> 122.7664 | R39: =+N39*(1+R40) -> 117.99575 | S39: =+O39*(1+S40) -> 115.25035 | T39: =+P39*(1+T40) -> 136.7808 | U39: =+Q39*(1+U40) -> 153.17465 | V39: =+R39*(1+V40) -> 146.93008 | W39: =+S39*(1+W40) -> 143.22886 | ... Y39: =+U39*(1+Y40) -> 189.61979 | AB39: =SUM(F39:I39) -> 263.1 | AC39: =SUM(J39:M39) -> 336.8 | AH39: From the FY2025 10-K. 2023 and 2026 quarters not disclosed in the documents reviewed; enter if you have them.
A40: YoY Growth (%) | J40: =+J39/F39 -1 -> 0.29015544 | K40: =+K39/G39 -1 -> 0.2800659 | L40: =+L39/H39 -1 -> 0.24355301 | M40: =+M39/I39 -1 -> 0.30655957 | N40: =+N39/J39 -1 -> 0.2583668 | O40: =+O39/K39 -1 -> 0.18404118 | P40: =+AVERAGE(J40:O40) -> 0.26045698 | Q40: =+P40*0.99 -> 0.25785241 | R40: =+Q40*0.99 -> 0.25527389 | S40: =+R40*0.99 -> 0.25272115 | T40: =+S40*0.99 -> 0.25019394 | U40: =+T40*0.99 -> 0.247692 | V40: =+U40*0.99 -> 0.24521508 | W40: =+V40*0.99 -> 0.24276293 | X40: =+W40*0.99 -> 0.2403353 | Y40: =+X40*0.99 -> 0.23793195
A41: Revenue per million impressions ($) | F41: ='Income Statement'!G9/(F39*1000) -> 1.1520035 | G41: ='Income Statement'!H9/(G39*1000) -> 1.1081878 | H41: ='Income Statement'!I9/(H39*1000) -> 1.0284527 | I41: ='Income Statement'!J9/(I39*1000) -> 1.1446051 | J41: ='Income Statement'!K9/(J39*1000) -> 0.85441767 | K41: ='Income Statement'!L9/(K39*1000) -> 0.91499356 | L41: ='Income Statement'!M9/(L39*1000) -> 0.78294931 | M41: ='Income Statement'!N9/(M39*1000) -> 0.82014344 | N41: ='Income Statement'!O9 / (N39*1000) -> 0.66560638 | O41: ='Income Statement'!P9 / (O39*1000) -> 0.85427174 | P41: =+AVERAGE(J41:O41) -> 0.81539702 | Q41: =+P41 -> 0.81539702 | R41: =+Q41 -> 0.81539702 | S41: =+R41 -> 0.81539702 | T41: =+S41 -> 0.81539702 | U41: =+T41 -> 0.81539702 | V41: =+U41 -> 0.81539702 | W41: =+V41 -> 0.81539702 | X41: =+W41 -> 0.81539702 | Y41: =+X41 -> 0.81539702 | AH41: Revenue divided by impressions processed.
A42: Cost of revenue per million impressions ($) | F42: ='Income Statement'!G10/(F39*1000) -> 0.4391019 | G42: ='Income Statement'!H10/(G39*1000) -> 0.41449753 | H42: ='Income Statement'!I10/(H39*1000) -> 0.36544413 | I42: ='Income Statement'!J10/(I39*1000) -> 0.33380187 | J42: ='Income Statement'!K10/(J39*1000) -> 0.34254351 | K42: ='Income Statement'!L10/(K39*1000) -> 0.34249678 | L42: ='Income Statement'!M10/(L39*1000) -> 0.29266129 | M42: ='Income Statement'!N10/(M39*1000) -> 0.26108607 | ... O42: ='Income Statement'!P10/(O39*1000) -> 0.28127174 | P42: =+AVERAGE(J42:O42) -> 0.29960919 | Q42: =+P42*0.99 -> 0.2966131 | R42: =+Q42*0.99 -> 0.29364697 | S42: =+R42*0.99 -> 0.2907105 | T42: =+S42*0.99 -> 0.28780339 | U42: =+T42*0.99 -> 0.28492536 | V42: =+U42*0.99 -> 0.2820761 | W42: =+V42*0.99 -> 0.27925534 | X42: =+W42*0.99 -> 0.27646279 | Y42: =+X42*0.99 -> 0.27369816 | AH42: Cost of revenue divided by impressions processed.

Sheet Income Statement
B1: PubMatic, Inc. (NASDAQ: PUBM): Income Statement
B2: $ in thousands except per share. Fiscal year ends Dec 31. Actuals through Q2 2026; forecast from Q3 2026. Q4 actuals = full year (10-K) less Q1 to Q3.
B4: Period | C4: Q1'23 | D4: Q2'23 | E4: Q3'23 | F4: Q4'23 | G4: Q1'24 | H4: Q2'24 | I4: Q3'24 | J4: Q4'24 | K4: Q1'25 | L4: Q2'25 | M4: Q3'25 | N4: Q4'25 | O4: Q1'26 | P4: Q2'26 | Q4: Q3'26 | R4: Q4'26 | S4: Q1'27 | T4: Q2'27 | U4: Q3'27 | V4: Q4'27 | W4: Q1'28 | X4: Q2'28 | Y4: Q3'28 | Z4: Q4'28 | AB4: FY2023A | AC4: FY2024A | AD4: FY2025A | AE4: FY2026E | AF4: FY2027E | AG4: FY2028E
B5: Period end | C5: 45016 | D5: 45107 | E5: 45199 | F5: 45291 | G5: 45382 | H5: 45473 | I5: 45565 | J5: 45657 | K5: 45747 | L5: 45838 | M5: 45930 | N5: 46022 | O5: 46112 | P5: 46203 | Q5: 46295 | R5: 46387 | S5: 46477 | T5: 46568 | U5: 46660 | V5: 46752 | W5: 46843 | X5: 46934 | Y5: 47026 | Z5: 47118 | AB5: 45291 | AC5: 45657 | AD5: 46022 | AE5: 46387 | AF5: 46752 | AG5: 47118
B6: Status | C6: Actual | D6: Actual | E6: Actual | F6: Actual | G6: Actual | H6: Actual | I6: Actual | J6: Actual | K6: Actual | L6: Actual | M6: Actual | N6: Actual | O6: Actual | P6: Actual | Q6: Forecast | R6: Forecast | S6: Forecast | T6: Forecast | U6: Forecast | V6: Forecast | W6: Forecast | X6: Forecast | Y6: Forecast | Z6: Forecast | AB6: Actual | AC6: Actual | AD6: Actual | AE6: 2A + 2E | AF6: Forecast | AG6: Forecast
A8: x | B8: Income statement ($ in thousands, except per share)
B9: Revenue | C9: 55407 | D9: 63330 | E9: 63677 | F9: ='10-K Data'!B9-SUM(C9:E9) -> 84600 | G9: 66701 | H9: 67267 | I9: 71786 | J9: ='10-K Data'!C9-SUM(G9:I9) -> 85502 | K9: 63825 | L9: 71095 | M9: 67960 | N9: ='10-K Data'!D9-SUM(K9:M9) -> 80046 | O9: 62567 | P9: 78593 | Q9: =+(Drivers!P$39*1000)*Drivers!P41 -> 89210.685 | R9: =+(Drivers!Q$39*1000)*Drivers!Q41 -> 100103.35 | S9: =+(Drivers!R$39*1000)*Drivers!R41 -> 96213.379 | T9: =+(Drivers!S$39*1000)*Drivers!S41 -> 93974.788 | U9: =+(Drivers!T$39*1000)*Drivers!T41 -> 111530.66 | V9: =+(Drivers!U$39*1000)*Drivers!U41 -> 124898.15 | W9: =+(Drivers!V$39*1000)*Drivers!V41 -> 119806.35 | X9: =+(Drivers!W$39*1000)*Drivers!W41 -> 116788.38 | ... Z9: =+(Drivers!Y$39*1000)*Drivers!Y41 -> 154615.41 | AB9: =SUM(C9:F9) -> 267014 | AC9: =SUM(G9:J9) -> 291256 | AD9: =SUM(K9:N9) -> 282926 | AE9: =SUM(O9:R9) -> 330474.04 | AF9: =SUM(S9:V9) -> 426616.98 | AG9: =SUM(W9:Z9) -> 529545.56
B10: Cost of revenue | C10: 23863 | D10: 25067 | E10: 26091 | F10: ='10-K Data'!B10-SUM(C10:E10) -> 24208 | G10: 25424 | H10: 25160 | I10: 25508 | J10: ='10-K Data'!C10-SUM(G10:I10) -> 24935 | K10: 25588 | L10: 26612 | M10: 25403 | N10: ='10-K Data'!D10-SUM(K10:M10) -> 25482 | O10: 26094 | P10: 25877 | Q10: =+(Drivers!P$39*1000)*Drivers!P42 -> 32779.542 | R10: =+(Drivers!Q$39*1000)*Drivers!Q42 -> 36414.121 | S10: =+(Drivers!R$39*1000)*Drivers!R42 -> 34649.093 | T10: =+(Drivers!S$39*1000)*Drivers!S42 -> 33504.485 | U10: =+(Drivers!T$39*1000)*Drivers!T42 -> 39365.978 | V10: =+(Drivers!U$39*1000)*Drivers!U42 -> 43643.342 | W10: =+(Drivers!V$39*1000)*Drivers!V42 -> 41445.465 | X10: =+(Drivers!W$39*1000)*Drivers!W42 -> 39997.424 | ... Z10: =+(Drivers!Y$39*1000)*Drivers!Y42 -> 51898.588 | AB10: =SUM(C10:F10) -> 99229 | AC10: =SUM(G10:J10) -> 101027 | AD10: =SUM(K10:N10) -> 103085 | AE10: =SUM(O10:R10) -> 121164.66 | AF10: =SUM(S10:V10) -> 151162.9 | AG10: =SUM(W10:Z10) -> 180244.51
B11: Gross profit | C11: =C9-C10 -> 31544 | D11: =D9-D10 -> 38263 | E11: =E9-E10 -> 37586 | F11: =F9-F10 -> 60392 | G11: =G9-G10 -> 41277 | H11: =H9-H10 -> 42107 | I11: =I9-I10 -> 46278 | J11: =J9-J10 -> 60567 | ... Z11: =Z9-Z10 -> 102716.82 | AB11: =AB9-AB10 -> 167785 | AC11: =AC9-AC10 -> 190229 | AD11: =AD9-AD10 -> 179841 | AE11: =AE9-AE10 -> 209309.37 | AF11: =AF9-AF10 -> 275454.08 | AG11: =AG9-AG10 -> 349301.05
B12: Gross margin % | C12: =IF(C9=0,0,C11/C9) -> 0.56931435 | D12: =IF(D9=0,0,D11/D9) -> 0.60418443 | E12: =IF(E9=0,0,E11/E9) -> 0.59026022 | F12: =IF(F9=0,0,F11/F9) -> 0.71385343 | G12: =IF(G9=0,0,G11/G9) -> 0.6188363 | H12: =IF(H9=0,0,H11/H9) -> 0.62596816 | I12: =IF(I9=0,0,I11/I9) -> 0.64466609 | J12: =IF(J9=0,0,J11/J9) -> 0.70836939 | ... Z12: =IF(Z9=0,0,Z11/Z9) -> 0.66433755 | AB12: =IF(AB9=0,0,AB11/AB9) -> 0.62837529 | AC12: =IF(AC9=0,0,AC11/AC9) -> 0.65313333 | AD12: =IF(AD9=0,0,AD11/AD9) -> 0.63564678 | AE12: =IF(AE9=0,0,AE11/AE9) -> 0.63336102 | AF12: =IF(AF9=0,0,AF11/AF9) -> 0.64567069 | AG12: =IF(AG9=0,0,AG11/AG9) -> 0.65962417
B14: Technology and development | C14: 6517 | D14: 6730 | E14: 6634 | F14: ='10-K Data'!B11-SUM(C14:E14) -> 6846 | G14: 7960 | H14: 8659 | I14: 8813 | J14: ='10-K Data'!C11-SUM(G14:I14) -> 7831 | K14: 8772 | L14: 9116 | M14: 9616 | N14: ='10-K Data'!D11-SUM(K14:M14) -> 6316 | O14: 7986 | P14: 9148 | Q14: =M14*(1+Drivers!P11) -> 9904.48 | R14: =N14*(1+Drivers!Q11) -> 6505.48 | S14: =O14*(1+Drivers!R11) -> 8225.58 | T14: =P14*(1+Drivers!S11) -> 9422.44 | U14: =Q14*(1+Drivers!T11) -> 10201.614 | V14: =R14*(1+Drivers!U11) -> 6700.6444 | W14: =S14*(1+Drivers!V11) -> 8472.3474 | X14: =T14*(1+Drivers!W11) -> 9705.1132 | ... Z14: =V14*(1+Drivers!Y11) -> 6901.6637 | AB14: =SUM(C14:F14) -> 26727 | AC14: =SUM(G14:J14) -> 33263 | AD14: =SUM(K14:N14) -> 33820 | AE14: =SUM(O14:R14) -> 33543.96 | AF14: =SUM(S14:V14) -> 34550.279 | AG14: =SUM(W14:Z14) -> 35586.787
B15: Sales and marketing | C15: 23127 | D15: 19810 | E15: 19513 | F15: ='10-K Data'!B12-SUM(C15:E15) -> 20353 | G15: 24815 | H15: 23095 | I15: 23696 | J15: ='10-K Data'!C12-SUM(G15:I15) -> 23763 | K15: 26799 | L15: 25200 | M15: 25732 | N15: ='10-K Data'!D12-SUM(K15:M15) -> 25209 | O15: 28965 | P15: 26130 | Q15: =M15*(1+Drivers!P12) -> 26761.28 | R15: =N15*(1+Drivers!Q12) -> 26217.36 | S15: =O15*(1+Drivers!R12) -> 30123.6 | T15: =P15*(1+Drivers!S12) -> 27175.2 | U15: =Q15*(1+Drivers!T12) -> 27831.731 | V15: =R15*(1+Drivers!U12) -> 27266.054 | W15: =S15*(1+Drivers!V12) -> 31328.544 | X15: =T15*(1+Drivers!W12) -> 28262.208 | ... Z15: =V15*(1+Drivers!Y12) -> 28356.697 | AB15: =SUM(C15:F15) -> 82803 | AC15: =SUM(G15:J15) -> 95369 | AD15: =SUM(K15:N15) -> 102940 | AE15: =SUM(O15:R15) -> 108073.64 | AF15: =SUM(S15:V15) -> 112396.59 | AG15: =SUM(W15:Z15) -> 116892.45
B16: General and administrative | C16: 12572 | D16: 18857 | E16: 12010 | F16: ='10-K Data'!B13-SUM(C16:E16) -> 12780 | G16: 14027 | H16: 14338 | I16: 15134 | J16: ='10-K Data'!C13-SUM(G16:I16) -> 14171 | K16: 14569 | L16: 15628 | M16: 15628 | N16: ='10-K Data'!D13-SUM(K16:M16) -> 14515 | O16: 14795 | P16: 16859 | Q16: =M16*(1+Drivers!P13) -> 16253.12 | R16: =N16*(1+Drivers!Q13) -> 15095.6 | S16: =O16*(1+Drivers!R13) -> 15386.8 | T16: =P16*(1+Drivers!S13) -> 17533.36 | U16: =Q16*(1+Drivers!T13) -> 16903.245 | V16: =R16*(1+Drivers!U13) -> 15699.424 | W16: =S16*(1+Drivers!V13) -> 16002.272 | X16: =T16*(1+Drivers!W13) -> 18234.694 | ... Z16: =V16*(1+Drivers!Y13) -> 16327.401 | AB16: =SUM(C16:F16) -> 56219 | AC16: =SUM(G16:J16) -> 57670 | AD16: =SUM(K16:N16) -> 60340 | AE16: =SUM(O16:R16) -> 63002.72 | AF16: =SUM(S16:V16) -> 65522.829 | AG16: =SUM(W16:Z16) -> 68143.742
B17: Total operating expenses | C17: =C14+C15+C16 -> 42216 | D17: =D14+D15+D16 -> 45397 | E17: =E14+E15+E16 -> 38157 | F17: =F14+F15+F16 -> 39979 | G17: =G14+G15+G16 -> 46802 | H17: =H14+H15+H16 -> 46092 | I17: =I14+I15+I16 -> 47643 | J17: =J14+J15+J16 -> 45765 | ... Z17: =Z14+Z15+Z16 -> 51585.761 | AB17: =AB14+AB15+AB16 -> 165749 | AC17: =AC14+AC15+AC16 -> 186302 | AD17: =AD14+AD15+AD16 -> 197100 | AE17: =AE14+AE15+AE16 -> 204620.32 | AF17: =AF14+AF15+AF16 -> 212469.69 | AG17: =AG14+AG15+AG16 -> 220622.98
B18: Operating income (loss) | C18: =C11-C17 -> -10672 | D18: =D11-D17 -> -7134 | E18: =E11-E17 -> -571 | F18: =F11-F17 -> 20413 | G18: =G11-G17 -> -5525 | H18: =H11-H17 -> -3985 | I18: =I11-I17 -> -1365 | J18: =J11-J17 -> 14802 | ... Z18: =Z11-Z17 -> 51131.064 | AB18: =AB11-AB17 -> 2036 | AC18: =AC11-AC17 -> 3927 | AD18: =AD11-AD17 -> -17259 | AE18: =AE11-AE17 -> 4689.0549 | AF18: =AF11-AF17 -> 62984.386 | AG18: =AG11-AG17 -> 128678.07
B19: Operating margin % | C19: =IF(C9=0,0,C18/C9) -> -0.19261104 | D19: =IF(D9=0,0,D18/D9) -> -0.11264803 | E19: =IF(E9=0,0,E18/E9) -> -0.008967131 | F19: =IF(F9=0,0,F18/F9) -> 0.24128842 | G19: =IF(G9=0,0,G18/G9) -> -0.082832341 | H19: =IF(H9=0,0,H18/H9) -> -0.05924153 | I19: =IF(I9=0,0,I18/I9) -> -0.01901485 | J19: =IF(J9=0,0,J18/J9) -> 0.17311876 | ... Z19: =IF(Z9=0,0,Z18/Z9) -> 0.33069836 | AB19: =IF(AB9=0,0,AB18/AB9) -> 0.0076250683 | AC19: =IF(AC9=0,0,AC18/AC9) -> 0.013482984 | AD19: =IF(AD9=0,0,AD18/AD9) -> -0.061001817 | AE19: =IF(AE9=0,0,AE18/AE9) -> 0.014188875 | AF19: =IF(AF9=0,0,AF18/AF9) -> 0.14763685 | AG19: =IF(AG9=0,0,AG18/AG9) -> 0.24299717
B21: Interest income | C21: 1891 | D21: 2176 | E21: 2246 | F21: ='10-K Data'!B15-SUM(C21:E21) -> 2515 | G21: 2564 | H21: 2340 | I21: 1969 | J21: ='10-K Data'!C15-SUM(G21:I21) -> 1604 | K21: 1593 | L21: 1379 | M21: 1198 | N21: ='10-K Data'!D15-SUM(K21:M21) -> 1285 | O21: 1215 | P21: 1213 | Q21: =('Balance Sheet'!P9+'Balance Sheet'!P10)*Drivers!P19/4 -> 1134.4327 | R21: =('Balance Sheet'!Q9+'Balance Sheet'!Q10)*Drivers!Q19/4 -> 1076.7897 | S21: =('Balance Sheet'!R9+'Balance Sheet'!R10)*Drivers!R19/4 -> 1165.9156 | T21: =('Balance Sheet'!S9+'Balance Sheet'!S10)*Drivers!S19/4 -> 1442.9784 | U21: =('Balance Sheet'!T9+'Balance Sheet'!T10)*Drivers!T19/4 -> 1567.8212 | V21: =('Balance Sheet'!U9+'Balance Sheet'!U10)*Drivers!U19/4 -> 1609.3297 | W21: =('Balance Sheet'!V9+'Balance Sheet'!V10)*Drivers!V19/4 -> 1835.4275 | X21: =('Balance Sheet'!W9+'Balance Sheet'!W10)*Drivers!W19/4 -> 2314.1323 | ... Z21: =('Balance Sheet'!Y9+'Balance Sheet'!Y10)*Drivers!Y19/4 -> 2751.6052 | AB21: =SUM(C21:F21) -> 8828 | AC21: =SUM(G21:J21) -> 8477 | AD21: =SUM(K21:N21) -> 5455 | AE21: =SUM(O21:R21) -> 4639.2224 | AF21: =SUM(S21:V21) -> 5786.0449 | AG21: =SUM(W21:Z21) -> 9481.9587
B22: Other income (expense), net | C22: -465 | D22: -221 | E22: 210 | F22: ='10-K Data'!B16-SUM(C22:E22) -> 117 | G22: 258 | H22: 4028 | I22: -930 | J22: ='10-K Data'!C16-SUM(G22:I22) -> 2014 | K22: -1014 | L22: -1988 | M22: -937 | N22: ='10-K Data'!D16-SUM(K22:M22) -> -211 | O22: -1053 | P22: 89 | Q22: =Drivers!P20 -> 0 | R22: =Drivers!Q20 -> 0 | S22: =Drivers!R20 -> 0 | T22: =Drivers!S20 -> 0 | U22: =Drivers!T20 -> 0 | V22: =Drivers!U20 -> 0 | W22: =Drivers!V20 -> 0 | X22: =Drivers!W20 -> 0 | ... Z22: =Drivers!Y20 -> 0 | AB22: =SUM(C22:F22) -> -359 | AC22: =SUM(G22:J22) -> 5370 | AD22: =SUM(K22:N22) -> -4150 | AE22: =SUM(O22:R22) -> -964 | AF22: =SUM(S22:V22) -> 0 | AG22: =SUM(W22:Z22) -> 0
B23: Total other income, net | C23: =C21+C22 -> 1426 | D23: =D21+D22 -> 1955 | E23: =E21+E22 -> 2456 | F23: =F21+F22 -> 2632 | G23: =G21+G22 -> 2822 | H23: =H21+H22 -> 6368 | I23: =I21+I22 -> 1039 | J23: =J21+J22 -> 3618 | ... Z23: =Z21+Z22 -> 2751.6052 | AB23: =AB21+AB22 -> 8469 | AC23: =AC21+AC22 -> 13847 | AD23: =AD21+AD22 -> 1305 | AE23: =AE21+AE22 -> 3675.2224 | AF23: =AF21+AF22 -> 5786.0449 | AG23: =AG21+AG22 -> 9481.9587
B24: Income (loss) before income taxes | C24: =C18+C23 -> -9246 | D24: =D18+D23 -> -5179 | E24: =E18+E23 -> 1885 | F24: =F18+F23 -> 23045 | G24: =G18+G23 -> -2703 | H24: =H18+H23 -> 2383 | I24: =I18+I23 -> -326 | J24: =J18+J23 -> 18420 | ... Z24: =Z18+Z23 -> 53882.669 | AB24: =AB18+AB23 -> 10505 | AC24: =AC18+AC23 -> 17774 | AD24: =AD18+AD23 -> -15954 | AE24: =AE18+AE23 -> 8364.2774 | AF24: =AF18+AF23 -> 68770.431 | AG24: =AG18+AG23 -> 138160.03
B25: Provision for (benefit from) income taxes | C25: -3375 | D25: 545 | E25: 111 | F25: ='10-K Data'!B17-SUM(C25:E25) -> 4343 | G25: -249 | H25: 412 | I25: 586 | J25: ='10-K Data'!C17-SUM(G25:I25) -> 4521 | K25: -1838 | L25: -862 | M25: -1706 | N25: ='10-K Data'!D17-SUM(K25:M25) -> 2914 | O25: -2601 | P25: 3083 | Q25: =Q24*Drivers!P21 -> 975.80605 | R25: =R24*Drivers!Q21 -> 3558.9922 | S25: =S24*Drivers!R21 -> 1888.7866 | T25: =T24*Drivers!S21 -> 1634.2791 | U25: =U24*Drivers!T21 -> 3947.1411 | V25: =V24*Drivers!U21 -> 6971.5837 | W25: =W24*Drivers!V21 -> 5122.5615 | X25: =X24*Drivers!W21 -> 4809.646 | ... Z25: =Z24*Drivers!Y21 -> 11315.36 | AB25: =SUM(C25:F25) -> 1624 | AC25: =SUM(G25:J25) -> 5270 | AD25: =SUM(K25:N25) -> -1492 | AE25: =SUM(O25:R25) -> 5016.7982 | AF25: =SUM(S25:V25) -> 14441.791 | AG25: =SUM(W25:Z25) -> 29013.606
B26: Effective tax rate % | C26: =IF(C24=0,0,C25/C24) -> 0.36502271 | D26: =IF(D24=0,0,D25/D24) -> -0.10523267 | E26: =IF(E24=0,0,E25/E24) -> 0.058885942 | F26: =IF(F24=0,0,F25/F24) -> 0.18845737 | G26: =IF(G24=0,0,G25/G24) -> 0.092119867 | H26: =IF(H24=0,0,H25/H24) -> 0.17289131 | I26: =IF(I24=0,0,I25/I24) -> -1.797546 | J26: =IF(J24=0,0,J25/J24) -> 0.24543974 | ... Z26: =IF(Z24=0,0,Z25/Z24) -> 0.21 | AB26: =IF(AB24=0,0,AB25/AB24) -> 0.15459305 | AC26: =IF(AC24=0,0,AC25/AC24) -> 0.29650051 | AD26: =IF(AD24=0,0,AD25/AD24) -> 0.093518867 | AE26: =IF(AE24=0,0,AE25/AE24) -> 0.5997886 | AF26: =IF(AF24=0,0,AF25/AF24) -> 0.21 | AG26: =IF(AG24=0,0,AG25/AG24) -> 0.21
B27: Net income (loss) | C27: =C24-C25 -> -5871 | D27: =D24-D25 -> -5724 | E27: =E24-E25 -> 1774 | F27: =F24-F25 -> 18702 | G27: =G24-G25 -> -2454 | H27: =H24-H25 -> 1971 | I27: =I24-I25 -> -912 | J27: =J24-J25 -> 13899 | ... Z27: =Z24-Z25 -> 42567.308 | AB27: =AB24-AB25 -> 8881 | AC27: =AC24-AC25 -> 12504 | AD27: =AD24-AD25 -> -14462 | AE27: =AE24-AE25 -> 3347.4791 | AF27: =AF24-AF25 -> 54328.641 | AG27: =AG24-AG25 -> 109146.42
B28: Net margin % | C28: =IF(C9=0,0,C27/C9) -> -0.10596134 | D28: =IF(D9=0,0,D27/D9) -> -0.090383704 | E28: =IF(E9=0,0,E27/E9) -> 0.027859353 | F28: =IF(F9=0,0,F27/F9) -> 0.22106383 | G28: =IF(G9=0,0,G27/G9) -> -0.036791053 | H28: =IF(H9=0,0,H27/H9) -> 0.029301143 | I28: =IF(I9=0,0,I27/I9) -> -0.012704427 | J28: =IF(J9=0,0,J27/J9) -> 0.1625576 | ... Z28: =IF(Z9=0,0,Z27/Z9) -> 0.2753109 | AB28: =IF(AB9=0,0,AB27/AB9) -> 0.033260428 | AC28: =IF(AC9=0,0,AC27/AC9) -> 0.042931304 | AD28: =IF(AD9=0,0,AD27/AD9) -> -0.051115839 | AE28: =IF(AE9=0,0,AE27/AE9) -> 0.010129326 | AF28: =IF(AF9=0,0,AF27/AF9) -> 0.12734758 | AG28: =IF(AG9=0,0,AG27/AG9) -> 0.20611338
B30: Weighted-average shares, basic (000s) | C30: 52740 | D30: 52029 | E30: 51638 | F30: =4*'10-K Data'!B19-SUM(C30:E30) -> 50633 | G30: 50039 | H30: 49780 | I30: 49056 | J30: =4*'10-K Data'!C19-SUM(G30:I30) -> 47977 | K30: 48346 | L30: 47185 | M30: 45933 | N30: =4*'10-K Data'!D19-SUM(K30:M30) -> 46568 | O30: 47120 | P30: 46106 | Q30: =Q31 -> 46106 | R30: =R31 -> 46106 | S30: =S31 -> 46106 | T30: =T31 -> 46106 | U30: =U31 -> 46106 | V30: =V31 -> 46106 | W30: =W31 -> 46106 | X30: =X31 -> 46106 | ... Z30: =Z31 -> 46106 | AB30: ='10-K Data'!B19 -> 51760 | AC30: ='10-K Data'!C19 -> 49213 | AD30: ='10-K Data'!D19 -> 47008 | AE30: =AVERAGE(O30:R30) -> 46359.5 | AF30: =AVERAGE(S30:V30) -> 46106 | AG30: =AVERAGE(W30:Z30) -> 46106
B31: Weighted-average shares, diluted (000s) | C31: 52740 | D31: 52029 | E31: 55979 | F31: 54940 | G31: 50039 | H31: 55577 | I31: 49056 | J31: 52620 | K31: 48346 | L31: 47185 | M31: 45933 | N31: 49320 | O31: 47120 | P31: 46106 | Q31: =Drivers!P22 -> 46106 | R31: =Drivers!Q22 -> 46106 | S31: =Drivers!R22 -> 46106 | T31: =Drivers!S22 -> 46106 | U31: =Drivers!T22 -> 46106 | V31: =Drivers!U22 -> 46106 | W31: =Drivers!V22 -> 46106 | X31: =Drivers!W22 -> 46106 | ... Z31: =Drivers!Y22 -> 46106 | AB31: ='10-K Data'!B20 -> 56027 | AC31: ='10-K Data'!C20 -> 54294 | AD31: ='10-K Data'!D20 -> 47008 | AE31: =AVERAGE(O31:R31) -> 46359.5 | AF31: =AVERAGE(S31:V31) -> 46106 | AG31: =AVERAGE(W31:Z31) -> 46106
B32: EPS, GAAP diluted ($) | C32: =IF(C27>0,C27/C31,C27/C30) -> -0.11131968 | D32: =IF(D27>0,D27/D31,D27/D30) -> -0.11001557 | E32: =IF(E27>0,E27/E31,E27/E30) -> 0.031690455 | F32: =IF(F27>0,F27/F31,F27/F30) -> 0.34040772 | G32: =IF(G27>0,G27/G31,G27/G30) -> -0.049041747 | H32: =IF(H27>0,H27/H31,H27/H30) -> 0.035464311 | I32: =IF(I27>0,I27/I31,I27/I30) -> -0.018590998 | J32: =IF(J27>0,J27/J31,J27/J30) -> 0.26413911 | ... P32: =IF(P27>0,P27/P31,P27/P30) -> -0.02607036 | Q32: =Q27/Q31 -> 0.079618475 | R32: =R27/R31 -> 0.29038714 | S32: =S27/S31 -> 0.15411086 | T32: =T27/T31 -> 0.13334495 | U32: =U27/U31 -> 0.32205719 | V32: =V27/V31 -> 0.56882909 | W32: =W27/W31 -> 0.4179627 | X32: =X27/X31 -> 0.39243114 | ... Z32: =Z27/Z31 -> 0.92324878 | AB32: =IF(AB27>0,AB27/AB31,AB27/AB30) -> 0.15851286 | AC32: =IF(AC27>0,AC27/AC31,AC27/AC30) -> 0.23030169 | AD32: =IF(AD27>0,AD27/AD31,AD27/AD30) -> -0.30764976 | AE32: =IF(AE27>0,AE27/AE31,AE27/AE30) -> 0.072206972 | AF32: =IF(AF27>0,AF27/AF31,AF27/AF30) -> 1.1783421 | AG32: =IF(AG27>0,AG27/AG31,AG27/AG30) -> 2.3672933
A34: x | B34: Growth and margin analysis
B35: Revenue growth, YoY % | G35: =G9/C9-1 -> 0.20383706 | H35: =H9/D9-1 -> 0.06216643 | I35: =I9/E9-1 -> 0.12734582 | J35: =J9/F9-1 -> 0.010661939 | K35: =K9/G9-1 -> -0.043117794 | L35: =L9/H9-1 -> 0.056907548 | M35: =M9/I9-1 -> -0.0532973 | N35: =N9/J9-1 -> -0.063811373 | ... Z35: =Z9/V9-1 -> 0.23793195 | AC35: =AC9/AB9-1 -> 0.090789247 | AD35: =AD9/AC9-1 -> -0.028600269 | AE35: =AE9/AD9-1 -> 0.16805821 | AF35: =AF9/AE9-1 -> 0.29092434 | AG35: =AG9/AF9-1 -> 0.24126696
B36: Revenue growth, QoQ % | D36: =D9/C9-1 -> 0.14299637 | E36: =E9/D9-1 -> 0.0054792357 | F36: =F9/E9-1 -> 0.32858018 | G36: =G9/F9-1 -> -0.2115721 | H36: =H9/G9-1 -> 0.0084856299 | I36: =I9/H9-1 -> 0.067180044 | J36: =J9/I9-1 -> 0.1910679 | K36: =K9/J9-1 -> -0.25352623 | ... Z36: =Z9/Y9-1 -> 0.11768499
B37: Gross profit growth, YoY % | G37: =G11/C11-1 -> 0.30855313 | H37: =H11/D11-1 -> 0.10046259 | I37: =I11/E11-1 -> 0.23125632 | J37: =J11/F11-1 -> 0.0028977348 | K37: =K11/G11-1 -> -0.073648763 | L37: =L11/H11-1 -> 0.056427672 | M37: =M11/I11-1 -> -0.080405376 | N37: =N11/J11-1 -> -0.099113379 | ... Z37: =Z11/V11-1 -> 0.26413222 | AC37: =AC11/AB11-1 -> 0.13376643 | AD37: =AD11/AC11-1 -> -0.054607867 | AE37: =AE11/AD11-1 -> 0.16385794 | AF37: =AF11/AE11-1 -> 0.31601406 | AG37: =AG11/AF11-1 -> 0.26809176
B38: Cost of revenue, % of revenue | C38: =IF(C9=0,0,C10/C9) -> 0.43068565 | D38: =IF(D9=0,0,D10/D9) -> 0.39581557 | E38: =IF(E9=0,0,E10/E9) -> 0.40973978 | F38: =IF(F9=0,0,F10/F9) -> 0.28614657 | G38: =IF(G9=0,0,G10/G9) -> 0.3811637 | H38: =IF(H9=0,0,H10/H9) -> 0.37403184 | I38: =IF(I9=0,0,I10/I9) -> 0.35533391 | J38: =IF(J9=0,0,J10/J9) -> 0.29163061 | ... Z38: =IF(Z9=0,0,Z10/Z9) -> 0.33566245 | AB38: =IF(AB9=0,0,AB10/AB9) -> 0.37162471 | AC38: =IF(AC9=0,0,AC10/AC9) -> 0.34686667 | AD38: =IF(AD9=0,0,AD10/AD9) -> 0.36435322 | AE38: =IF(AE9=0,0,AE10/AE9) -> 0.36663898 | AF38: =IF(AF9=0,0,AF10/AF9) -> 0.35432931 | AG38: =IF(AG9=0,0,AG10/AG9) -> 0.34037583
B39: Technology and development, % of revenue | C39: =IF(C9=0,0,C14/C9) -> 0.11762052 | D39: =IF(D9=0,0,D14/D9) -> 0.10626875 | E39: =IF(E9=0,0,E14/E9) -> 0.10418204 | F39: =IF(F9=0,0,F14/F9) -> 0.080921986 | G39: =IF(G9=0,0,G14/G9) -> 0.11933854 | H39: =IF(H9=0,0,H14/H9) -> 0.12872582 | I39: =IF(I9=0,0,I14/I9) -> 0.12276767 | J39: =IF(J9=0,0,J14/J9) -> 0.091588501 | ... Z39: =IF(Z9=0,0,Z14/Z9) -> 0.044637618 | AB39: =IF(AB9=0,0,AB14/AB9) -> 0.10009588 | AC39: =IF(AC9=0,0,AC14/AC9) -> 0.11420537 | AD39: =IF(AD9=0,0,AD14/AD9) -> 0.11953656 | AE39: =IF(AE9=0,0,AE14/AE9) -> 0.10150256 | AF39: =IF(AF9=0,0,AF14/AF9) -> 0.080986648 | AG39: =IF(AG9=0,0,AG14/AG9) -> 0.067202503
B40: Sales and marketing, % of revenue | C40: =IF(C9=0,0,C15/C9) -> 0.41740213 | D40: =IF(D9=0,0,D15/D9) -> 0.31280594 | E40: =IF(E9=0,0,E15/E9) -> 0.30643718 | F40: =IF(F9=0,0,F15/F9) -> 0.2405792 | G40: =IF(G9=0,0,G15/G9) -> 0.3720334 | H40: =IF(H9=0,0,H15/H9) -> 0.34333328 | I40: =IF(I9=0,0,I15/I9) -> 0.33009222 | J40: =IF(J9=0,0,J15/J9) -> 0.27792332 | ... Z40: =IF(Z9=0,0,Z15/Z9) -> 0.18340149 | AB40: =IF(AB9=0,0,AB15/AB9) -> 0.31010734 | AC40: =IF(AC9=0,0,AC15/AC9) -> 0.32744046 | AD40: =IF(AD9=0,0,AD15/AD9) -> 0.36384072 | AE40: =IF(AE9=0,0,AE15/AE9) -> 0.32702611 | AF40: =IF(AF9=0,0,AF15/AF9) -> 0.26346018 | AG40: =IF(AG9=0,0,AG15/AG9) -> 0.22074106
B41: General and administrative, % of revenue | C41: =IF(C9=0,0,C16/C9) -> 0.22690274 | D41: =IF(D9=0,0,D16/D9) -> 0.29775778 | E41: =IF(E9=0,0,E16/E9) -> 0.18860813 | F41: =IF(F9=0,0,F16/F9) -> 0.15106383 | G41: =IF(G9=0,0,G16/G9) -> 0.2102967 | H41: =IF(H9=0,0,H16/H9) -> 0.21315058 | I41: =IF(I9=0,0,I16/I9) -> 0.21082105 | J41: =IF(J9=0,0,J16/J9) -> 0.16573881 | ... Z41: =IF(Z9=0,0,Z16/Z9) -> 0.10560009 | AB41: =IF(AB9=0,0,AB16/AB9) -> 0.21054701 | AC41: =IF(AC9=0,0,AC16/AC9) -> 0.1980045 | AD41: =IF(AD9=0,0,AD16/AD9) -> 0.21327131 | AE41: =IF(AE9=0,0,AE16/AE9) -> 0.19064348 | AF41: =IF(AF9=0,0,AF16/AF9) -> 0.15358702 | AG41: =IF(AG9=0,0,AG16/AG9) -> 0.12868344
B42: Total operating expenses, % of revenue | C42: =IF(C9=0,0,C17/C9) -> 0.76192539 | D42: =IF(D9=0,0,D17/D9) -> 0.71683246 | E42: =IF(E9=0,0,E17/E9) -> 0.59922735 | F42: =IF(F9=0,0,F17/F9) -> 0.47256501 | G42: =IF(G9=0,0,G17/G9) -> 0.70166864 | H42: =IF(H9=0,0,H17/H9) -> 0.68520969 | I42: =IF(I9=0,0,I17/I9) -> 0.66368094 | J42: =IF(J9=0,0,J17/J9) -> 0.53525064 | ... Z42: =IF(Z9=0,0,Z17/Z9) -> 0.33363919 | AB42: =IF(AB9=0,0,AB17/AB9) -> 0.62075022 | AC42: =IF(AC9=0,0,AC17/AC9) -> 0.63965034 | AD42: =IF(AD9=0,0,AD17/AD9) -> 0.69664859 | AE42: =IF(AE9=0,0,AE17/AE9) -> 0.61917215 | AF42: =IF(AF9=0,0,AF17/AF9) -> 0.49803384 | AG42: =IF(AG9=0,0,AG17/AG9) -> 0.416627
A44: x | B44: Adjusted EBITDA reconciliation (company definition)
B45: Net income (loss) | C45: =C27 -> -5871 | D45: =D27 -> -5724 | E45: =E27 -> 1774 | F45: =F27 -> 18702 | G45: =G27 -> -2454 | H45: =H27 -> 1971 | I45: =I27 -> -912 | J45: =J27 -> 13899 | ... Z45: =Z27 -> 42567.308 | AB45: =AB27 -> 8881 | AC45: =AC27 -> 12504 | AD45: =AD27 -> -14462 | AE45: =AE27 -> 3347.4791 | AF45: =AF27 -> 54328.641 | AG45: =AG27 -> 109146.42
B46: Plus: stock-based compensation | C46: =C59 -> 7059 | D46: =D59 -> 7266 | E46: =E59 -> 7200 | F46: =F59 -> 7337 | G46: =G59 -> 9111 | H46: =H59 -> 9699 | I46: =I59 -> 9457 | J46: =J59 -> 9409 | ... Z46: =Z59 -> 17007.695 | AB46: =AB59 -> 28862 | AC46: =AC59 -> 37676 | AD46: =AD59 -> 38378 | AE46: =AE59 -> 37659.544 | AF46: =AF59 -> 46927.868 | AG46: =AG59 -> 58250.011
B47: Plus: depreciation and amortization | C47: =C62 -> 11432 | D47: =D62 -> 10898 | E47: =E62 -> 11401 | F47: =F62 -> 11039 | G47: =G62 -> 11212 | H47: =H62 -> 11336 | I47: =I62 -> 11383 | J47: =J62 -> 11421 | ... Z47: =Z62 -> 19326.927 | AB47: =AB62 -> 44770 | AC47: =AC62 -> 45352 | AD47: =AD62 -> 43769 | AE47: =AE62 -> 43659.255 | AF47: =AF62 -> 53327.122 | AG47: =AG62 -> 66193.195
...

Sheet Balance Sheet
B1: PubMatic, Inc. (NASDAQ: PUBM): Balance Sheet
B2: $ in thousands. Quarter-end balances. History begins Q4 2023; forecast balances are driven by the Drivers tab and the cash flow statement. Annual columns show year-end balances.
B4: Period | C4: Q1'23 | D4: Q2'23 | E4: Q3'23 | F4: Q4'23 | G4: Q1'24 | H4: Q2'24 | I4: Q3'24 | J4: Q4'24 | K4: Q1'25 | L4: Q2'25 | M4: Q3'25 | N4: Q4'25 | O4: Q1'26 | P4: Q2'26 | Q4: Q3'26 | R4: Q4'26 | S4: Q1'27 | T4: Q2'27 | U4: Q3'27 | V4: Q4'27 | W4: Q1'28 | X4: Q2'28 | Y4: Q3'28 | Z4: Q4'28 | AB4: FY2023A | AC4: FY2024A | AD4: FY2025A | AE4: FY2026E | AF4: FY2027E | AG4: FY2028E
B5: Period end | C5: 45016 | D5: 45107 | E5: 45199 | F5: 45291 | G5: 45382 | H5: 45473 | I5: 45565 | J5: 45657 | K5: 45747 | L5: 45838 | M5: 45930 | N5: 46022 | O5: 46112 | P5: 46203 | Q5: 46295 | R5: 46387 | S5: 46477 | T5: 46568 | U5: 46660 | V5: 46752 | W5: 46843 | X5: 46934 | Y5: 47026 | Z5: 47118 | AB5: 45291 | AC5: 45657 | AD5: 46022 | AE5: 46387 | AF5: 46752 | AG5: 47118
